ERROR:django.request:Internal Server Error: /update_email
Traceback (most recent call last):
  File "D:\django projects\exel_data\venv\lib\site-packages\django\utils\datastructures.py", line 76, in __getitem__
    list_ = super().__getitem__(key)
KeyError: 'file'

During handling of the above exception, another exception occurred:

Traceback (most recent call last):
  File "D:\django projects\exel_data\venv\lib\site-packages\django\core\handlers\exception.py", line 47, in inner
    response = get_response(request)
  File "D:\django projects\exel_data\venv\lib\site-packages\django\core\handlers\base.py", line 181, in _get_response
    response = wrapped_callback(request, *callback_args, **callback_kwargs)
  File "D:\django projects\exel_data\project\email.py", line 12, in update_email
    myfile = request.FILES['file']
  File "D:\django projects\exel_data\venv\lib\site-packages\django\utils\datastructures.py", line 78, in __getitem__
    raise MultiValueDictKeyError(key)
django.utils.datastructures.MultiValueDictKeyError: 'file'
INFO:django.utils.autoreload:D:\django projects\exel_data\project\email.py changed, reloading.
INFO:django.utils.autoreload:D:\django projects\exel_data\project\email.py changed, reloading.
ERROR:django.request:Internal Server Error: /update_email
Traceback (most recent call last):
  File "D:\django projects\exel_data\venv\lib\site-packages\django\db\backends\utils.py", line 84, in _execute
    return self.cursor.execute(sql, params)
  File "D:\django projects\exel_data\venv\lib\site-packages\django\db\backends\mysql\base.py", line 73, in execute
    return self.cursor.execute(query, args)
  File "D:\django projects\exel_data\venv\lib\site-packages\MySQLdb\cursors.py", line 206, in execute
    res = self._query(query)
  File "D:\django projects\exel_data\venv\lib\site-packages\MySQLdb\cursors.py", line 319, in _query
    db.query(q)
  File "D:\django projects\exel_data\venv\lib\site-packages\MySQLdb\connections.py", line 254, in query
    _mysql.connection.query(self, query)
MySQLdb._exceptions.IntegrityError: (1062, "Duplicate entry 'mo@gmail.com' for key 'project_person.project_person_email_82bd4bf0_uniq'")

The above exception was the direct cause of the following exception:

Traceback (most recent call last):
  File "D:\django projects\exel_data\venv\lib\site-packages\django\core\handlers\exception.py", line 47, in inner
    response = get_response(request)
  File "D:\django projects\exel_data\venv\lib\site-packages\django\core\handlers\base.py", line 181, in _get_response
    response = wrapped_callback(request, *callback_args, **callback_kwargs)
  File "D:\django projects\exel_data\project\email.py", line 33, in update_email
    check_index.save()
  File "D:\django projects\exel_data\venv\lib\site-packages\django\db\models\base.py", line 726, in save
    self.save_base(using=using, force_insert=force_insert,
  File "D:\django projects\exel_data\venv\lib\site-packages\django\db\models\base.py", line 763, in save_base
    updated = self._save_table(
  File "D:\django projects\exel_data\venv\lib\site-packages\django\db\models\base.py", line 845, in _save_table
    updated = self._do_update(base_qs, using, pk_val, values, update_fields,
  File "D:\django projects\exel_data\venv\lib\site-packages\django\db\models\base.py", line 899, in _do_update
    return filtered._update(values) > 0
  File "D:\django projects\exel_data\venv\lib\site-packages\django\db\models\query.py", line 802, in _update
    return query.get_compiler(self.db).execute_sql(CURSOR)
  File "D:\django projects\exel_data\venv\lib\site-packages\django\db\models\sql\compiler.py", line 1559, in execute_sql
    cursor = super().execute_sql(result_type)
  File "D:\django projects\exel_data\venv\lib\site-packages\django\db\models\sql\compiler.py", line 1175, in execute_sql
    cursor.execute(sql, params)
  File "D:\django projects\exel_data\venv\lib\site-packages\django\db\backends\utils.py", line 98, in execute
    return super().execute(sql, params)
  File "D:\django projects\exel_data\venv\lib\site-packages\django\db\backends\utils.py", line 66, in execute
    return self._execute_with_wrappers(sql, params, many=False, executor=self._execute)
  File "D:\django projects\exel_data\venv\lib\site-packages\django\db\backends\utils.py", line 75, in _execute_with_wrappers
    return executor(sql, params, many, context)
  File "D:\django projects\exel_data\venv\lib\site-packages\django\db\backends\utils.py", line 84, in _execute
    return self.cursor.execute(sql, params)
  File "D:\django projects\exel_data\venv\lib\site-packages\django\db\utils.py", line 90, in __exit__
    raise dj_exc_value.with_traceback(traceback) from exc_value
  File "D:\django projects\exel_data\venv\lib\site-packages\django\db\backends\utils.py", line 84, in _execute
    return self.cursor.execute(sql, params)
  File "D:\django projects\exel_data\venv\lib\site-packages\django\db\backends\mysql\base.py", line 73, in execute
    return self.cursor.execute(query, args)
  File "D:\django projects\exel_data\venv\lib\site-packages\MySQLdb\cursors.py", line 206, in execute
    res = self._query(query)
  File "D:\django projects\exel_data\venv\lib\site-packages\MySQLdb\cursors.py", line 319, in _query
    db.query(q)
  File "D:\django projects\exel_data\venv\lib\site-packages\MySQLdb\connections.py", line 254, in query
    _mysql.connection.query(self, query)
django.db.utils.IntegrityError: (1062, "Duplicate entry 'mo@gmail.com' for key 'project_person.project_person_email_82bd4bf0_uniq'")
INFO:django.utils.autoreload:D:\django projects\exel_data\exel_data\urls.py changed, reloading.
INFO:django.utils.autoreload:D:\django projects\exel_data\project\update_emails_from_excel_file.py changed, reloading.
INFO:django.utils.autoreload:D:\django projects\exel_data\exel_data\settings.py changed, reloading.
INFO:django.utils.autoreload:D:\django projects\exel_data\exel_data\urls.py changed, reloading.
DEBUG:root:('Index: 4', 'First Name: nan', 'Last Name: n', 'Email: n@gmail.com')
DEBUG:root:('Updates Row : 6', 'Invalid Row: 1')
INFO:django.utils.autoreload:D:\django projects\exel_data\project\update_emails_from_excel_file.py changed, reloading.
INFO:django.utils.autoreload:D:\django projects\exel_data\project\models.py changed, reloading.
INFO:django.utils.autoreload:D:\django projects\exel_data\project\models.py changed, reloading.
INFO:django.utils.autoreload:D:\django projects\exel_data\project\views.py changed, reloading.
INFO:django.utils.autoreload:D:\django projects\exel_data\project\update_emails_from_excel_file.py changed, reloading.
INFO:django.utils.autoreload:D:\django projects\exel_data\project\update_emails_from_excel_file.py changed, reloading.
INFO:django.utils.autoreload:D:\django projects\exel_data\project\models.py changed, reloading.
INFO:django.utils.autoreload:D:\django projects\exel_data\project\models.py changed, reloading.
INFO:django.utils.autoreload:D:\django projects\exel_data\project\models.py changed, reloading.
INFO:django.utils.autoreload:D:\django projects\exel_data\project\models.py changed, reloading.
INFO:django.utils.autoreload:D:\django projects\exel_data\project\store_data.py changed, reloading.
INFO:django.utils.autoreload:D:\django projects\exel_data\exel_data\urls.py changed, reloading.
INFO:django.utils.autoreload:D:\django projects\exel_data\project\views.py changed, reloading.
ERROR:django.request:Internal Server Error: /upload_excel
Traceback (most recent call last):
  File "D:\django projects\exel_data\venv\lib\site-packages\django\core\handlers\exception.py", line 47, in inner
    response = get_response(request)
  File "D:\django projects\exel_data\venv\lib\site-packages\django\core\handlers\base.py", line 181, in _get_response
    response = wrapped_callback(request, *callback_args, **callback_kwargs)
  File "D:\django projects\exel_data\project\views.py", line 30, in Import_excel_file
    save_obj(row)
  File "D:\django projects\exel_data\project\store_data.py", line 8, in save_obj
    , country=row.country, city=row.city)
  File "D:\django projects\exel_data\venv\lib\site-packages\pandas\core\generic.py", line 5487, in __getattr__
    return object.__getattribute__(self, name)
AttributeError: 'Series' object has no attribute 'country'
INFO:django.utils.autoreload:D:\django projects\exel_data\project\store_data.py changed, reloading.
ERROR:django.request:Internal Server Error: /upload_excel
Traceback (most recent call last):
  File "D:\django projects\exel_data\venv\lib\site-packages\django\core\handlers\exception.py", line 47, in inner
    response = get_response(request)
  File "D:\django projects\exel_data\venv\lib\site-packages\django\core\handlers\base.py", line 181, in _get_response
    response = wrapped_callback(request, *callback_args, **callback_kwargs)
  File "D:\django projects\exel_data\project\views.py", line 30, in Import_excel_file
    save_obj(row)
  File "D:\django projects\exel_data\project\store_data.py", line 8, in save_obj
    , country=row.country, city=row.city)
  File "D:\django projects\exel_data\venv\lib\site-packages\pandas\core\generic.py", line 5487, in __getattr__
    return object.__getattribute__(self, name)
AttributeError: 'Series' object has no attribute 'country'
ERROR:django.request:Internal Server Error: /upload_excel
Traceback (most recent call last):
  File "D:\django projects\exel_data\venv\lib\site-packages\django\db\backends\utils.py", line 84, in _execute
    return self.cursor.execute(sql, params)
  File "D:\django projects\exel_data\venv\lib\site-packages\django\db\backends\mysql\base.py", line 73, in execute
    return self.cursor.execute(query, args)
  File "D:\django projects\exel_data\venv\lib\site-packages\MySQLdb\cursors.py", line 206, in execute
    res = self._query(query)
  File "D:\django projects\exel_data\venv\lib\site-packages\MySQLdb\cursors.py", line 319, in _query
    db.query(q)
  File "D:\django projects\exel_data\venv\lib\site-packages\MySQLdb\connections.py", line 254, in query
    _mysql.connection.query(self, query)
MySQLdb._exceptions.DataError: (1406, "Data too long for column 'title' at row 1")

The above exception was the direct cause of the following exception:

Traceback (most recent call last):
  File "D:\django projects\exel_data\venv\lib\site-packages\django\core\handlers\exception.py", line 47, in inner
    response = get_response(request)
  File "D:\django projects\exel_data\venv\lib\site-packages\django\core\handlers\base.py", line 181, in _get_response
    response = wrapped_callback(request, *callback_args, **callback_kwargs)
  File "D:\django projects\exel_data\project\views.py", line 30, in Import_excel_file
    save_obj(row)
  File "D:\django projects\exel_data\project\store_data.py", line 7, in save_obj
    Person.objects.create(first_name=row.first_name, last_name=row.last_name, email=row.email, created_at=now, title=row
  File "D:\django projects\exel_data\venv\lib\site-packages\django\db\models\manager.py", line 85, in manager_method
    return getattr(self.get_queryset(), name)(*args, **kwargs)
  File "D:\django projects\exel_data\venv\lib\site-packages\django\db\models\query.py", line 453, in create
    obj.save(force_insert=True, using=self.db)
  File "D:\django projects\exel_data\venv\lib\site-packages\django\db\models\base.py", line 726, in save
    self.save_base(using=using, force_insert=force_insert,
  File "D:\django projects\exel_data\venv\lib\site-packages\django\db\models\base.py", line 763, in save_base
    updated = self._save_table(
  File "D:\django projects\exel_data\venv\lib\site-packages\django\db\models\base.py", line 868, in _save_table
    results = self._do_insert(cls._base_manager, using, fields, returning_fields, raw)
  File "D:\django projects\exel_data\venv\lib\site-packages\django\db\models\base.py", line 906, in _do_insert
    return manager._insert(
  File "D:\django projects\exel_data\venv\lib\site-packages\django\db\models\manager.py", line 85, in manager_method
    return getattr(self.get_queryset(), name)(*args, **kwargs)
  File "D:\django projects\exel_data\venv\lib\site-packages\django\db\models\query.py", line 1270, in _insert
    return query.get_compiler(using=using).execute_sql(returning_fields)
  File "D:\django projects\exel_data\venv\lib\site-packages\django\db\models\sql\compiler.py", line 1416, in execute_sql
    cursor.execute(sql, params)
  File "D:\django projects\exel_data\venv\lib\site-packages\django\db\backends\utils.py", line 98, in execute
    return super().execute(sql, params)
  File "D:\django projects\exel_data\venv\lib\site-packages\django\db\backends\utils.py", line 66, in execute
    return self._execute_with_wrappers(sql, params, many=False, executor=self._execute)
  File "D:\django projects\exel_data\venv\lib\site-packages\django\db\backends\utils.py", line 75, in _execute_with_wrappers
    return executor(sql, params, many, context)
  File "D:\django projects\exel_data\venv\lib\site-packages\django\db\backends\utils.py", line 84, in _execute
    return self.cursor.execute(sql, params)
  File "D:\django projects\exel_data\venv\lib\site-packages\django\db\utils.py", line 90, in __exit__
    raise dj_exc_value.with_traceback(traceback) from exc_value
  File "D:\django projects\exel_data\venv\lib\site-packages\django\db\backends\utils.py", line 84, in _execute
    return self.cursor.execute(sql, params)
  File "D:\django projects\exel_data\venv\lib\site-packages\django\db\backends\mysql\base.py", line 73, in execute
    return self.cursor.execute(query, args)
  File "D:\django projects\exel_data\venv\lib\site-packages\MySQLdb\cursors.py", line 206, in execute
    res = self._query(query)
  File "D:\django projects\exel_data\venv\lib\site-packages\MySQLdb\cursors.py", line 319, in _query
    db.query(q)
  File "D:\django projects\exel_data\venv\lib\site-packages\MySQLdb\connections.py", line 254, in query
    _mysql.connection.query(self, query)
django.db.utils.DataError: (1406, "Data too long for column 'title' at row 1")
ERROR:django.request:Internal Server Error: /upload_excel
Traceback (most recent call last):
  File "D:\django projects\exel_data\venv\lib\site-packages\django\db\backends\utils.py", line 84, in _execute
    return self.cursor.execute(sql, params)
  File "D:\django projects\exel_data\venv\lib\site-packages\django\db\backends\mysql\base.py", line 73, in execute
    return self.cursor.execute(query, args)
  File "D:\django projects\exel_data\venv\lib\site-packages\MySQLdb\cursors.py", line 206, in execute
    res = self._query(query)
  File "D:\django projects\exel_data\venv\lib\site-packages\MySQLdb\cursors.py", line 319, in _query
    db.query(q)
  File "D:\django projects\exel_data\venv\lib\site-packages\MySQLdb\connections.py", line 254, in query
    _mysql.connection.query(self, query)
MySQLdb._exceptions.DataError: (1406, "Data too long for column 'title' at row 1")

The above exception was the direct cause of the following exception:

Traceback (most recent call last):
  File "D:\django projects\exel_data\venv\lib\site-packages\django\core\handlers\exception.py", line 47, in inner
    response = get_response(request)
  File "D:\django projects\exel_data\venv\lib\site-packages\django\core\handlers\base.py", line 181, in _get_response
    response = wrapped_callback(request, *callback_args, **callback_kwargs)
  File "D:\django projects\exel_data\project\views.py", line 30, in Import_excel_file
    save_obj(row)
  File "D:\django projects\exel_data\project\store_data.py", line 7, in save_obj
    Person.objects.create(first_name=row.first_name, last_name=row.last_name, email=row.email, created_at=now, title=row
  File "D:\django projects\exel_data\venv\lib\site-packages\django\db\models\manager.py", line 85, in manager_method
    return getattr(self.get_queryset(), name)(*args, **kwargs)
  File "D:\django projects\exel_data\venv\lib\site-packages\django\db\models\query.py", line 453, in create
    obj.save(force_insert=True, using=self.db)
  File "D:\django projects\exel_data\venv\lib\site-packages\django\db\models\base.py", line 726, in save
    self.save_base(using=using, force_insert=force_insert,
  File "D:\django projects\exel_data\venv\lib\site-packages\django\db\models\base.py", line 763, in save_base
    updated = self._save_table(
  File "D:\django projects\exel_data\venv\lib\site-packages\django\db\models\base.py", line 868, in _save_table
    results = self._do_insert(cls._base_manager, using, fields, returning_fields, raw)
  File "D:\django projects\exel_data\venv\lib\site-packages\django\db\models\base.py", line 906, in _do_insert
    return manager._insert(
  File "D:\django projects\exel_data\venv\lib\site-packages\django\db\models\manager.py", line 85, in manager_method
    return getattr(self.get_queryset(), name)(*args, **kwargs)
  File "D:\django projects\exel_data\venv\lib\site-packages\django\db\models\query.py", line 1270, in _insert
    return query.get_compiler(using=using).execute_sql(returning_fields)
  File "D:\django projects\exel_data\venv\lib\site-packages\django\db\models\sql\compiler.py", line 1416, in execute_sql
    cursor.execute(sql, params)
  File "D:\django projects\exel_data\venv\lib\site-packages\django\db\backends\utils.py", line 98, in execute
    return super().execute(sql, params)
  File "D:\django projects\exel_data\venv\lib\site-packages\django\db\backends\utils.py", line 66, in execute
    return self._execute_with_wrappers(sql, params, many=False, executor=self._execute)
  File "D:\django projects\exel_data\venv\lib\site-packages\django\db\backends\utils.py", line 75, in _execute_with_wrappers
    return executor(sql, params, many, context)
  File "D:\django projects\exel_data\venv\lib\site-packages\django\db\backends\utils.py", line 84, in _execute
    return self.cursor.execute(sql, params)
  File "D:\django projects\exel_data\venv\lib\site-packages\django\db\utils.py", line 90, in __exit__
    raise dj_exc_value.with_traceback(traceback) from exc_value
  File "D:\django projects\exel_data\venv\lib\site-packages\django\db\backends\utils.py", line 84, in _execute
    return self.cursor.execute(sql, params)
  File "D:\django projects\exel_data\venv\lib\site-packages\django\db\backends\mysql\base.py", line 73, in execute
    return self.cursor.execute(query, args)
  File "D:\django projects\exel_data\venv\lib\site-packages\MySQLdb\cursors.py", line 206, in execute
    res = self._query(query)
  File "D:\django projects\exel_data\venv\lib\site-packages\MySQLdb\cursors.py", line 319, in _query
    db.query(q)
  File "D:\django projects\exel_data\venv\lib\site-packages\MySQLdb\connections.py", line 254, in query
    _mysql.connection.query(self, query)
django.db.utils.DataError: (1406, "Data too long for column 'title' at row 1")
INFO:django.utils.autoreload:D:\django projects\exel_data\project\models.py changed, reloading.
ERROR:django.request:Internal Server Error: /upload_excel
Traceback (most recent call last):
  File "D:\django projects\exel_data\venv\lib\site-packages\django\db\backends\utils.py", line 84, in _execute
    return self.cursor.execute(sql, params)
  File "D:\django projects\exel_data\venv\lib\site-packages\django\db\backends\mysql\base.py", line 73, in execute
    return self.cursor.execute(query, args)
  File "D:\django projects\exel_data\venv\lib\site-packages\MySQLdb\cursors.py", line 206, in execute
    res = self._query(query)
  File "D:\django projects\exel_data\venv\lib\site-packages\MySQLdb\cursors.py", line 319, in _query
    db.query(q)
  File "D:\django projects\exel_data\venv\lib\site-packages\MySQLdb\connections.py", line 254, in query
    _mysql.connection.query(self, query)
MySQLdb._exceptions.DataError: (1406, "Data too long for column 'title' at row 1")

The above exception was the direct cause of the following exception:

Traceback (most recent call last):
  File "D:\django projects\exel_data\venv\lib\site-packages\django\core\handlers\exception.py", line 47, in inner
    response = get_response(request)
  File "D:\django projects\exel_data\venv\lib\site-packages\django\core\handlers\base.py", line 181, in _get_response
    response = wrapped_callback(request, *callback_args, **callback_kwargs)
  File "D:\django projects\exel_data\project\views.py", line 30, in Import_excel_file
    save_obj(row)
  File "D:\django projects\exel_data\project\store_data.py", line 7, in save_obj
    Person.objects.create(first_name=row.first_name, last_name=row.last_name, email=row.email, created_at=now, title=row
  File "D:\django projects\exel_data\venv\lib\site-packages\django\db\models\manager.py", line 85, in manager_method
    return getattr(self.get_queryset(), name)(*args, **kwargs)
  File "D:\django projects\exel_data\venv\lib\site-packages\django\db\models\query.py", line 453, in create
    obj.save(force_insert=True, using=self.db)
  File "D:\django projects\exel_data\venv\lib\site-packages\django\db\models\base.py", line 726, in save
    self.save_base(using=using, force_insert=force_insert,
  File "D:\django projects\exel_data\venv\lib\site-packages\django\db\models\base.py", line 763, in save_base
    updated = self._save_table(
  File "D:\django projects\exel_data\venv\lib\site-packages\django\db\models\base.py", line 868, in _save_table
    results = self._do_insert(cls._base_manager, using, fields, returning_fields, raw)
  File "D:\django projects\exel_data\venv\lib\site-packages\django\db\models\base.py", line 906, in _do_insert
    return manager._insert(
  File "D:\django projects\exel_data\venv\lib\site-packages\django\db\models\manager.py", line 85, in manager_method
    return getattr(self.get_queryset(), name)(*args, **kwargs)
  File "D:\django projects\exel_data\venv\lib\site-packages\django\db\models\query.py", line 1270, in _insert
    return query.get_compiler(using=using).execute_sql(returning_fields)
  File "D:\django projects\exel_data\venv\lib\site-packages\django\db\models\sql\compiler.py", line 1416, in execute_sql
    cursor.execute(sql, params)
  File "D:\django projects\exel_data\venv\lib\site-packages\django\db\backends\utils.py", line 98, in execute
    return super().execute(sql, params)
  File "D:\django projects\exel_data\venv\lib\site-packages\django\db\backends\utils.py", line 66, in execute
    return self._execute_with_wrappers(sql, params, many=False, executor=self._execute)
  File "D:\django projects\exel_data\venv\lib\site-packages\django\db\backends\utils.py", line 75, in _execute_with_wrappers
    return executor(sql, params, many, context)
  File "D:\django projects\exel_data\venv\lib\site-packages\django\db\backends\utils.py", line 84, in _execute
    return self.cursor.execute(sql, params)
  File "D:\django projects\exel_data\venv\lib\site-packages\django\db\utils.py", line 90, in __exit__
    raise dj_exc_value.with_traceback(traceback) from exc_value
  File "D:\django projects\exel_data\venv\lib\site-packages\django\db\backends\utils.py", line 84, in _execute
    return self.cursor.execute(sql, params)
  File "D:\django projects\exel_data\venv\lib\site-packages\django\db\backends\mysql\base.py", line 73, in execute
    return self.cursor.execute(query, args)
  File "D:\django projects\exel_data\venv\lib\site-packages\MySQLdb\cursors.py", line 206, in execute
    res = self._query(query)
  File "D:\django projects\exel_data\venv\lib\site-packages\MySQLdb\cursors.py", line 319, in _query
    db.query(q)
  File "D:\django projects\exel_data\venv\lib\site-packages\MySQLdb\connections.py", line 254, in query
    _mysql.connection.query(self, query)
django.db.utils.DataError: (1406, "Data too long for column 'title' at row 1")
ERROR:django.request:Internal Server Error: /upload_excel
Traceback (most recent call last):
  File "D:\django projects\exel_data\venv\lib\site-packages\django\db\backends\utils.py", line 84, in _execute
    return self.cursor.execute(sql, params)
  File "D:\django projects\exel_data\venv\lib\site-packages\django\db\backends\mysql\base.py", line 73, in execute
    return self.cursor.execute(query, args)
  File "D:\django projects\exel_data\venv\lib\site-packages\MySQLdb\cursors.py", line 206, in execute
    res = self._query(query)
  File "D:\django projects\exel_data\venv\lib\site-packages\MySQLdb\cursors.py", line 319, in _query
    db.query(q)
  File "D:\django projects\exel_data\venv\lib\site-packages\MySQLdb\connections.py", line 254, in query
    _mysql.connection.query(self, query)
MySQLdb._exceptions.DataError: (1406, "Data too long for column 'title' at row 1")

The above exception was the direct cause of the following exception:

Traceback (most recent call last):
  File "D:\django projects\exel_data\venv\lib\site-packages\django\core\handlers\exception.py", line 47, in inner
    response = get_response(request)
  File "D:\django projects\exel_data\venv\lib\site-packages\django\core\handlers\base.py", line 181, in _get_response
    response = wrapped_callback(request, *callback_args, **callback_kwargs)
  File "D:\django projects\exel_data\project\views.py", line 30, in Import_excel_file
    save_obj(row)
  File "D:\django projects\exel_data\project\store_data.py", line 7, in save_obj
    Person.objects.create(first_name=row.first_name, last_name=row.last_name, email=row.email, created_at=now, title=row
  File "D:\django projects\exel_data\venv\lib\site-packages\django\db\models\manager.py", line 85, in manager_method
    return getattr(self.get_queryset(), name)(*args, **kwargs)
  File "D:\django projects\exel_data\venv\lib\site-packages\django\db\models\query.py", line 453, in create
    obj.save(force_insert=True, using=self.db)
  File "D:\django projects\exel_data\venv\lib\site-packages\django\db\models\base.py", line 726, in save
    self.save_base(using=using, force_insert=force_insert,
  File "D:\django projects\exel_data\venv\lib\site-packages\django\db\models\base.py", line 763, in save_base
    updated = self._save_table(
  File "D:\django projects\exel_data\venv\lib\site-packages\django\db\models\base.py", line 868, in _save_table
    results = self._do_insert(cls._base_manager, using, fields, returning_fields, raw)
  File "D:\django projects\exel_data\venv\lib\site-packages\django\db\models\base.py", line 906, in _do_insert
    return manager._insert(
  File "D:\django projects\exel_data\venv\lib\site-packages\django\db\models\manager.py", line 85, in manager_method
    return getattr(self.get_queryset(), name)(*args, **kwargs)
  File "D:\django projects\exel_data\venv\lib\site-packages\django\db\models\query.py", line 1270, in _insert
    return query.get_compiler(using=using).execute_sql(returning_fields)
  File "D:\django projects\exel_data\venv\lib\site-packages\django\db\models\sql\compiler.py", line 1416, in execute_sql
    cursor.execute(sql, params)
  File "D:\django projects\exel_data\venv\lib\site-packages\django\db\backends\utils.py", line 98, in execute
    return super().execute(sql, params)
  File "D:\django projects\exel_data\venv\lib\site-packages\django\db\backends\utils.py", line 66, in execute
    return self._execute_with_wrappers(sql, params, many=False, executor=self._execute)
  File "D:\django projects\exel_data\venv\lib\site-packages\django\db\backends\utils.py", line 75, in _execute_with_wrappers
    return executor(sql, params, many, context)
  File "D:\django projects\exel_data\venv\lib\site-packages\django\db\backends\utils.py", line 84, in _execute
    return self.cursor.execute(sql, params)
  File "D:\django projects\exel_data\venv\lib\site-packages\django\db\utils.py", line 90, in __exit__
    raise dj_exc_value.with_traceback(traceback) from exc_value
  File "D:\django projects\exel_data\venv\lib\site-packages\django\db\backends\utils.py", line 84, in _execute
    return self.cursor.execute(sql, params)
  File "D:\django projects\exel_data\venv\lib\site-packages\django\db\backends\mysql\base.py", line 73, in execute
    return self.cursor.execute(query, args)
  File "D:\django projects\exel_data\venv\lib\site-packages\MySQLdb\cursors.py", line 206, in execute
    res = self._query(query)
  File "D:\django projects\exel_data\venv\lib\site-packages\MySQLdb\cursors.py", line 319, in _query
    db.query(q)
  File "D:\django projects\exel_data\venv\lib\site-packages\MySQLdb\connections.py", line 254, in query
    _mysql.connection.query(self, query)
django.db.utils.DataError: (1406, "Data too long for column 'title' at row 1")
INFO:django.utils.autoreload:D:\django projects\exel_data\project\models.py changed, reloading.
ERROR:django.request:Internal Server Error: /upload_excel
Traceback (most recent call last):
  File "D:\django projects\exel_data\venv\lib\site-packages\django\db\backends\utils.py", line 84, in _execute
    return self.cursor.execute(sql, params)
  File "D:\django projects\exel_data\venv\lib\site-packages\django\db\backends\mysql\base.py", line 73, in execute
    return self.cursor.execute(query, args)
  File "D:\django projects\exel_data\venv\lib\site-packages\MySQLdb\cursors.py", line 206, in execute
    res = self._query(query)
  File "D:\django projects\exel_data\venv\lib\site-packages\MySQLdb\cursors.py", line 319, in _query
    db.query(q)
  File "D:\django projects\exel_data\venv\lib\site-packages\MySQLdb\connections.py", line 254, in query
    _mysql.connection.query(self, query)
MySQLdb._exceptions.DataError: (1406, "Data too long for column 'title' at row 1")

The above exception was the direct cause of the following exception:

Traceback (most recent call last):
  File "D:\django projects\exel_data\venv\lib\site-packages\django\core\handlers\exception.py", line 47, in inner
    response = get_response(request)
  File "D:\django projects\exel_data\venv\lib\site-packages\django\core\handlers\base.py", line 181, in _get_response
    response = wrapped_callback(request, *callback_args, **callback_kwargs)
  File "D:\django projects\exel_data\project\views.py", line 30, in Import_excel_file
    save_obj(row)
  File "D:\django projects\exel_data\project\store_data.py", line 7, in save_obj
    Person.objects.create(first_name=row.first_name, last_name=row.last_name, email=row.email, created_at=now, title=row
  File "D:\django projects\exel_data\venv\lib\site-packages\django\db\models\manager.py", line 85, in manager_method
    return getattr(self.get_queryset(), name)(*args, **kwargs)
  File "D:\django projects\exel_data\venv\lib\site-packages\django\db\models\query.py", line 453, in create
    obj.save(force_insert=True, using=self.db)
  File "D:\django projects\exel_data\venv\lib\site-packages\django\db\models\base.py", line 726, in save
    self.save_base(using=using, force_insert=force_insert,
  File "D:\django projects\exel_data\venv\lib\site-packages\django\db\models\base.py", line 763, in save_base
    updated = self._save_table(
  File "D:\django projects\exel_data\venv\lib\site-packages\django\db\models\base.py", line 868, in _save_table
    results = self._do_insert(cls._base_manager, using, fields, returning_fields, raw)
  File "D:\django projects\exel_data\venv\lib\site-packages\django\db\models\base.py", line 906, in _do_insert
    return manager._insert(
  File "D:\django projects\exel_data\venv\lib\site-packages\django\db\models\manager.py", line 85, in manager_method
    return getattr(self.get_queryset(), name)(*args, **kwargs)
  File "D:\django projects\exel_data\venv\lib\site-packages\django\db\models\query.py", line 1270, in _insert
    return query.get_compiler(using=using).execute_sql(returning_fields)
  File "D:\django projects\exel_data\venv\lib\site-packages\django\db\models\sql\compiler.py", line 1416, in execute_sql
    cursor.execute(sql, params)
  File "D:\django projects\exel_data\venv\lib\site-packages\django\db\backends\utils.py", line 98, in execute
    return super().execute(sql, params)
  File "D:\django projects\exel_data\venv\lib\site-packages\django\db\backends\utils.py", line 66, in execute
    return self._execute_with_wrappers(sql, params, many=False, executor=self._execute)
  File "D:\django projects\exel_data\venv\lib\site-packages\django\db\backends\utils.py", line 75, in _execute_with_wrappers
    return executor(sql, params, many, context)
  File "D:\django projects\exel_data\venv\lib\site-packages\django\db\backends\utils.py", line 84, in _execute
    return self.cursor.execute(sql, params)
  File "D:\django projects\exel_data\venv\lib\site-packages\django\db\utils.py", line 90, in __exit__
    raise dj_exc_value.with_traceback(traceback) from exc_value
  File "D:\django projects\exel_data\venv\lib\site-packages\django\db\backends\utils.py", line 84, in _execute
    return self.cursor.execute(sql, params)
  File "D:\django projects\exel_data\venv\lib\site-packages\django\db\backends\mysql\base.py", line 73, in execute
    return self.cursor.execute(query, args)
  File "D:\django projects\exel_data\venv\lib\site-packages\MySQLdb\cursors.py", line 206, in execute
    res = self._query(query)
  File "D:\django projects\exel_data\venv\lib\site-packages\MySQLdb\cursors.py", line 319, in _query
    db.query(q)
  File "D:\django projects\exel_data\venv\lib\site-packages\MySQLdb\connections.py", line 254, in query
    _mysql.connection.query(self, query)
django.db.utils.DataError: (1406, "Data too long for column 'title' at row 1")
INFO:django.utils.autoreload:D:\django projects\exel_data\project\models.py changed, reloading.
ERROR:django.request:Internal Server Error: /upload_excel
Traceback (most recent call last):
  File "D:\django projects\exel_data\venv\lib\site-packages\django\core\handlers\exception.py", line 47, in inner
    response = get_response(request)
  File "D:\django projects\exel_data\venv\lib\site-packages\django\core\handlers\base.py", line 181, in _get_response
    response = wrapped_callback(request, *callback_args, **callback_kwargs)
  File "D:\django projects\exel_data\project\views.py", line 30, in Import_excel_file
    save_obj(row)
  File "D:\django projects\exel_data\project\store_data.py", line 7, in save_obj
    Person.objects.create(first_name=row.first_name, last_name=row.last_name, email=row.email, created_at=now, title=row
  File "D:\django projects\exel_data\venv\lib\site-packages\django\db\models\manager.py", line 85, in manager_method
    return getattr(self.get_queryset(), name)(*args, **kwargs)
  File "D:\django projects\exel_data\venv\lib\site-packages\django\db\models\query.py", line 451, in create
    obj = self.model(**kwargs)
  File "D:\django projects\exel_data\venv\lib\site-packages\django\db\models\base.py", line 503, in __init__
    raise TypeError("%s() got an unexpected keyword argument '%s'" % (cls.__name__, kwarg))
TypeError: Person() got an unexpected keyword argument 'title'
INFO:django.utils.autoreload:D:\django projects\exel_data\project\models.py changed, reloading.
ERROR:django.request:Internal Server Error: /upload_excel
Traceback (most recent call last):
  File "D:\django projects\exel_data\venv\lib\site-packages\django\db\backends\utils.py", line 84, in _execute
    return self.cursor.execute(sql, params)
  File "D:\django projects\exel_data\venv\lib\site-packages\django\db\backends\mysql\base.py", line 73, in execute
    return self.cursor.execute(query, args)
  File "D:\django projects\exel_data\venv\lib\site-packages\MySQLdb\cursors.py", line 206, in execute
    res = self._query(query)
  File "D:\django projects\exel_data\venv\lib\site-packages\MySQLdb\cursors.py", line 319, in _query
    db.query(q)
  File "D:\django projects\exel_data\venv\lib\site-packages\MySQLdb\connections.py", line 254, in query
    _mysql.connection.query(self, query)
MySQLdb._exceptions.DataError: (1406, "Data too long for column 'title' at row 1")

The above exception was the direct cause of the following exception:

Traceback (most recent call last):
  File "D:\django projects\exel_data\venv\lib\site-packages\django\core\handlers\exception.py", line 47, in inner
    response = get_response(request)
  File "D:\django projects\exel_data\venv\lib\site-packages\django\core\handlers\base.py", line 181, in _get_response
    response = wrapped_callback(request, *callback_args, **callback_kwargs)
  File "D:\django projects\exel_data\project\views.py", line 30, in Import_excel_file
    save_obj(row)
  File "D:\django projects\exel_data\project\store_data.py", line 7, in save_obj
    Person.objects.create(first_name=row.first_name, last_name=row.last_name, email=row.email, created_at=now, title=row
  File "D:\django projects\exel_data\venv\lib\site-packages\django\db\models\manager.py", line 85, in manager_method
    return getattr(self.get_queryset(), name)(*args, **kwargs)
  File "D:\django projects\exel_data\venv\lib\site-packages\django\db\models\query.py", line 453, in create
    obj.save(force_insert=True, using=self.db)
  File "D:\django projects\exel_data\venv\lib\site-packages\django\db\models\base.py", line 726, in save
    self.save_base(using=using, force_insert=force_insert,
  File "D:\django projects\exel_data\venv\lib\site-packages\django\db\models\base.py", line 763, in save_base
    updated = self._save_table(
  File "D:\django projects\exel_data\venv\lib\site-packages\django\db\models\base.py", line 868, in _save_table
    results = self._do_insert(cls._base_manager, using, fields, returning_fields, raw)
  File "D:\django projects\exel_data\venv\lib\site-packages\django\db\models\base.py", line 906, in _do_insert
    return manager._insert(
  File "D:\django projects\exel_data\venv\lib\site-packages\django\db\models\manager.py", line 85, in manager_method
    return getattr(self.get_queryset(), name)(*args, **kwargs)
  File "D:\django projects\exel_data\venv\lib\site-packages\django\db\models\query.py", line 1270, in _insert
    return query.get_compiler(using=using).execute_sql(returning_fields)
  File "D:\django projects\exel_data\venv\lib\site-packages\django\db\models\sql\compiler.py", line 1416, in execute_sql
    cursor.execute(sql, params)
  File "D:\django projects\exel_data\venv\lib\site-packages\django\db\backends\utils.py", line 98, in execute
    return super().execute(sql, params)
  File "D:\django projects\exel_data\venv\lib\site-packages\django\db\backends\utils.py", line 66, in execute
    return self._execute_with_wrappers(sql, params, many=False, executor=self._execute)
  File "D:\django projects\exel_data\venv\lib\site-packages\django\db\backends\utils.py", line 75, in _execute_with_wrappers
    return executor(sql, params, many, context)
  File "D:\django projects\exel_data\venv\lib\site-packages\django\db\backends\utils.py", line 84, in _execute
    return self.cursor.execute(sql, params)
  File "D:\django projects\exel_data\venv\lib\site-packages\django\db\utils.py", line 90, in __exit__
    raise dj_exc_value.with_traceback(traceback) from exc_value
  File "D:\django projects\exel_data\venv\lib\site-packages\django\db\backends\utils.py", line 84, in _execute
    return self.cursor.execute(sql, params)
  File "D:\django projects\exel_data\venv\lib\site-packages\django\db\backends\mysql\base.py", line 73, in execute
    return self.cursor.execute(query, args)
  File "D:\django projects\exel_data\venv\lib\site-packages\MySQLdb\cursors.py", line 206, in execute
    res = self._query(query)
  File "D:\django projects\exel_data\venv\lib\site-packages\MySQLdb\cursors.py", line 319, in _query
    db.query(q)
  File "D:\django projects\exel_data\venv\lib\site-packages\MySQLdb\connections.py", line 254, in query
    _mysql.connection.query(self, query)
django.db.utils.DataError: (1406, "Data too long for column 'title' at row 1")
INFO:django.utils.autoreload:D:\django projects\exel_data\project\models.py changed, reloading.
ERROR:django.request:Internal Server Error: /upload_excel
Traceback (most recent call last):
  File "D:\django projects\exel_data\venv\lib\site-packages\django\core\handlers\exception.py", line 47, in inner
    response = get_response(request)
  File "D:\django projects\exel_data\venv\lib\site-packages\django\core\handlers\base.py", line 181, in _get_response
    response = wrapped_callback(request, *callback_args, **callback_kwargs)
  File "D:\django projects\exel_data\project\views.py", line 30, in Import_excel_file
    save_obj(row)
  File "D:\django projects\exel_data\project\store_data.py", line 7, in save_obj
    Person.objects.create(first_name=row.first_name, last_name=row.last_name, email=row.email, created_at=now, title=row
  File "D:\django projects\exel_data\venv\lib\site-packages\django\db\models\manager.py", line 85, in manager_method
    return getattr(self.get_queryset(), name)(*args, **kwargs)
  File "D:\django projects\exel_data\venv\lib\site-packages\django\db\models\query.py", line 451, in create
    obj = self.model(**kwargs)
  File "D:\django projects\exel_data\venv\lib\site-packages\django\db\models\base.py", line 503, in __init__
    raise TypeError("%s() got an unexpected keyword argument '%s'" % (cls.__name__, kwarg))
TypeError: Person() got an unexpected keyword argument 'title'
ERROR:django.request:Internal Server Error: /upload_excel
Traceback (most recent call last):
  File "D:\django projects\exel_data\venv\lib\site-packages\django\core\handlers\exception.py", line 47, in inner
    response = get_response(request)
  File "D:\django projects\exel_data\venv\lib\site-packages\django\core\handlers\base.py", line 181, in _get_response
    response = wrapped_callback(request, *callback_args, **callback_kwargs)
  File "D:\django projects\exel_data\project\views.py", line 30, in Import_excel_file
    save_obj(row)
  File "D:\django projects\exel_data\project\store_data.py", line 7, in save_obj
    Person.objects.create(first_name=row.first_name, last_name=row.last_name, email=row.email, created_at=now, title=row
  File "D:\django projects\exel_data\venv\lib\site-packages\django\db\models\manager.py", line 85, in manager_method
    return getattr(self.get_queryset(), name)(*args, **kwargs)
  File "D:\django projects\exel_data\venv\lib\site-packages\django\db\models\query.py", line 451, in create
    obj = self.model(**kwargs)
  File "D:\django projects\exel_data\venv\lib\site-packages\django\db\models\base.py", line 503, in __init__
    raise TypeError("%s() got an unexpected keyword argument '%s'" % (cls.__name__, kwarg))
TypeError: Person() got an unexpected keyword argument 'title'
INFO:django.utils.autoreload:D:\django projects\exel_data\project\store_data.py changed, reloading.
DEBUG:root:('Valid Row : 3', 'Invalid Row: 0')
WARNING:django.request:Not Found: /update_email
ERROR:django.request:Internal Server Error: /update_excel
Traceback (most recent call last):
  File "D:\django projects\exel_data\venv\lib\site-packages\django\core\handlers\exception.py", line 47, in inner
    response = get_response(request)
  File "D:\django projects\exel_data\venv\lib\site-packages\django\core\handlers\base.py", line 181, in _get_response
    response = wrapped_callback(request, *callback_args, **callback_kwargs)
  File "D:\django projects\exel_data\project\update_row_from_excel_file.py", line 31, in update_email_excel_file
    get_row.title = row.title
  File "D:\django projects\exel_data\venv\lib\site-packages\pandas\core\generic.py", line 5487, in __getattr__
    return object.__getattribute__(self, name)
AttributeError: 'Series' object has no attribute 'title'
INFO:django.utils.autoreload:D:\django projects\exel_data\project\update_row_from_excel_file.py changed, reloading.
DEBUG:root:('Updates Row : 3', 'Invalid Row: 0')
WARNING:django.request:Not Found: /favicon.ico
WARNING:django.security.csrf:Forbidden (CSRF token missing or incorrect.): /upload_excel
ERROR:django.request:Internal Server Error: /upload_excel
Traceback (most recent call last):
  File "D:\django projects\exel_data\venv\lib\site-packages\django\db\backends\utils.py", line 84, in _execute
    return self.cursor.execute(sql, params)
  File "D:\django projects\exel_data\venv\lib\site-packages\django\db\backends\mysql\base.py", line 73, in execute
    return self.cursor.execute(query, args)
  File "D:\django projects\exel_data\venv\lib\site-packages\MySQLdb\cursors.py", line 206, in execute
    res = self._query(query)
  File "D:\django projects\exel_data\venv\lib\site-packages\MySQLdb\cursors.py", line 319, in _query
    db.query(q)
  File "D:\django projects\exel_data\venv\lib\site-packages\MySQLdb\connections.py", line 254, in query
    _mysql.connection.query(self, query)
MySQLdb._exceptions.IntegrityError: (1062, "Duplicate entry 'ali@gmail.com' for key 'project_person.project_person_email_82bd4bf0_uniq'")

The above exception was the direct cause of the following exception:

Traceback (most recent call last):
  File "D:\django projects\exel_data\venv\lib\site-packages\django\core\handlers\exception.py", line 47, in inner
    response = get_response(request)
  File "D:\django projects\exel_data\venv\lib\site-packages\django\core\handlers\base.py", line 181, in _get_response
    response = wrapped_callback(request, *callback_args, **callback_kwargs)
  File "D:\django projects\exel_data\project\views.py", line 29, in Import_excel_file
    save_obj(row)
  File "D:\django projects\exel_data\project\store_data.py", line 7, in save_obj
    Person.objects.create(first_name=row.first_name, last_name=row.last_name, email=row.email, created_at=now
  File "D:\django projects\exel_data\venv\lib\site-packages\django\db\models\manager.py", line 85, in manager_method
    return getattr(self.get_queryset(), name)(*args, **kwargs)
  File "D:\django projects\exel_data\venv\lib\site-packages\django\db\models\query.py", line 453, in create
    obj.save(force_insert=True, using=self.db)
  File "D:\django projects\exel_data\venv\lib\site-packages\django\db\models\base.py", line 726, in save
    self.save_base(using=using, force_insert=force_insert,
  File "D:\django projects\exel_data\venv\lib\site-packages\django\db\models\base.py", line 763, in save_base
    updated = self._save_table(
  File "D:\django projects\exel_data\venv\lib\site-packages\django\db\models\base.py", line 868, in _save_table
    results = self._do_insert(cls._base_manager, using, fields, returning_fields, raw)
  File "D:\django projects\exel_data\venv\lib\site-packages\django\db\models\base.py", line 906, in _do_insert
    return manager._insert(
  File "D:\django projects\exel_data\venv\lib\site-packages\django\db\models\manager.py", line 85, in manager_method
    return getattr(self.get_queryset(), name)(*args, **kwargs)
  File "D:\django projects\exel_data\venv\lib\site-packages\django\db\models\query.py", line 1270, in _insert
    return query.get_compiler(using=using).execute_sql(returning_fields)
  File "D:\django projects\exel_data\venv\lib\site-packages\django\db\models\sql\compiler.py", line 1416, in execute_sql
    cursor.execute(sql, params)
  File "D:\django projects\exel_data\venv\lib\site-packages\django\db\backends\utils.py", line 98, in execute
    return super().execute(sql, params)
  File "D:\django projects\exel_data\venv\lib\site-packages\django\db\backends\utils.py", line 66, in execute
    return self._execute_with_wrappers(sql, params, many=False, executor=self._execute)
  File "D:\django projects\exel_data\venv\lib\site-packages\django\db\backends\utils.py", line 75, in _execute_with_wrappers
    return executor(sql, params, many, context)
  File "D:\django projects\exel_data\venv\lib\site-packages\django\db\backends\utils.py", line 84, in _execute
    return self.cursor.execute(sql, params)
  File "D:\django projects\exel_data\venv\lib\site-packages\django\db\utils.py", line 90, in __exit__
    raise dj_exc_value.with_traceback(traceback) from exc_value
  File "D:\django projects\exel_data\venv\lib\site-packages\django\db\backends\utils.py", line 84, in _execute
    return self.cursor.execute(sql, params)
  File "D:\django projects\exel_data\venv\lib\site-packages\django\db\backends\mysql\base.py", line 73, in execute
    return self.cursor.execute(query, args)
  File "D:\django projects\exel_data\venv\lib\site-packages\MySQLdb\cursors.py", line 206, in execute
    res = self._query(query)
  File "D:\django projects\exel_data\venv\lib\site-packages\MySQLdb\cursors.py", line 319, in _query
    db.query(q)
  File "D:\django projects\exel_data\venv\lib\site-packages\MySQLdb\connections.py", line 254, in query
    _mysql.connection.query(self, query)
django.db.utils.IntegrityError: (1062, "Duplicate entry 'ali@gmail.com' for key 'project_person.project_person_email_82bd4bf0_uniq'")
INFO:django.utils.autoreload:D:\django projects\exel_data\project\models.py changed, reloading.
INFO:django.utils.autoreload:D:\django projects\exel_data\project\models.py changed, reloading.
INFO:django.utils.autoreload:D:\django projects\exel_data\project\models.py changed, reloading.
ERROR:django.request:Internal Server Error: /upload_excel
Traceback (most recent call last):
  File "D:\django projects\exel_data\venv\lib\site-packages\django\core\handlers\exception.py", line 47, in inner
    response = get_response(request)
  File "D:\django projects\exel_data\venv\lib\site-packages\django\core\handlers\base.py", line 181, in _get_response
    response = wrapped_callback(request, *callback_args, **callback_kwargs)
  File "D:\django projects\exel_data\project\views.py", line 29, in Import_excel_file
    save_obj(row)
  File "D:\django projects\exel_data\project\store_data.py", line 7, in save_obj
    Person.objects.create(first_name=row.first_name, last_name=row.last_name, email=row.email, created_at=now, job_title=row.job_title
  File "D:\django projects\exel_data\venv\lib\site-packages\django\db\models\manager.py", line 85, in manager_method
    return getattr(self.get_queryset(), name)(*args, **kwargs)
  File "D:\django projects\exel_data\venv\lib\site-packages\django\db\models\query.py", line 453, in create
    obj.save(force_insert=True, using=self.db)
  File "D:\django projects\exel_data\venv\lib\site-packages\django\db\models\base.py", line 726, in save
    self.save_base(using=using, force_insert=force_insert,
  File "D:\django projects\exel_data\venv\lib\site-packages\django\db\models\base.py", line 763, in save_base
    updated = self._save_table(
  File "D:\django projects\exel_data\venv\lib\site-packages\django\db\models\base.py", line 868, in _save_table
    results = self._do_insert(cls._base_manager, using, fields, returning_fields, raw)
  File "D:\django projects\exel_data\venv\lib\site-packages\django\db\models\base.py", line 906, in _do_insert
    return manager._insert(
  File "D:\django projects\exel_data\venv\lib\site-packages\django\db\models\manager.py", line 85, in manager_method
    return getattr(self.get_queryset(), name)(*args, **kwargs)
  File "D:\django projects\exel_data\venv\lib\site-packages\django\db\models\query.py", line 1270, in _insert
    return query.get_compiler(using=using).execute_sql(returning_fields)
  File "D:\django projects\exel_data\venv\lib\site-packages\django\db\models\sql\compiler.py", line 1415, in execute_sql
    for sql, params in self.as_sql():
  File "D:\django projects\exel_data\venv\lib\site-packages\django\db\models\sql\compiler.py", line 1358, in as_sql
    value_rows = [
  File "D:\django projects\exel_data\venv\lib\site-packages\django\db\models\sql\compiler.py", line 1359, in <listcomp>
    [self.prepare_value(field, self.pre_save_val(field, obj)) for field in fields]
  File "D:\django projects\exel_data\venv\lib\site-packages\django\db\models\sql\compiler.py", line 1359, in <listcomp>
    [self.prepare_value(field, self.pre_save_val(field, obj)) for field in fields]
  File "D:\django projects\exel_data\venv\lib\site-packages\django\db\models\sql\compiler.py", line 1300, in prepare_value
    value = field.get_db_prep_save(value, connection=self.connection)
  File "D:\django projects\exel_data\venv\lib\site-packages\django\db\models\fields\__init__.py", line 842, in get_db_prep_save
    return self.get_db_prep_value(value, connection=connection, prepared=False)
  File "D:\django projects\exel_data\venv\lib\site-packages\django\db\models\fields\__init__.py", line 1427, in get_db_prep_value
    value = self.get_prep_value(value)
  File "D:\django projects\exel_data\venv\lib\site-packages\django\db\models\fields\__init__.py", line 1406, in get_prep_value
    value = super().get_prep_value(value)
  File "D:\django projects\exel_data\venv\lib\site-packages\django\db\models\fields\__init__.py", line 1266, in get_prep_value
    return self.to_python(value)
  File "D:\django projects\exel_data\venv\lib\site-packages\django\db\models\fields\__init__.py", line 1367, in to_python
    parsed = parse_datetime(value)
  File "D:\django projects\exel_data\venv\lib\site-packages\django\utils\dateparse.py", line 107, in parse_datetime
    match = datetime_re.match(value)
TypeError: expected string or bytes-like object
INFO:django.utils.autoreload:D:\django projects\exel_data\project\models.py changed, reloading.
ERROR:django.request:Internal Server Error: /upload_excel
Traceback (most recent call last):
  File "D:\django projects\exel_data\venv\lib\site-packages\django\core\handlers\exception.py", line 47, in inner
    response = get_response(request)
  File "D:\django projects\exel_data\venv\lib\site-packages\django\core\handlers\base.py", line 181, in _get_response
    response = wrapped_callback(request, *callback_args, **callback_kwargs)
  File "D:\django projects\exel_data\project\views.py", line 29, in Import_excel_file
    save_obj(row)
  File "D:\django projects\exel_data\project\store_data.py", line 7, in save_obj
    Person.objects.create(first_name=row.first_name, last_name=row.last_name, email=row.email, created_at=now, job_title=row.job_title
  File "D:\django projects\exel_data\venv\lib\site-packages\django\db\models\manager.py", line 85, in manager_method
    return getattr(self.get_queryset(), name)(*args, **kwargs)
  File "D:\django projects\exel_data\venv\lib\site-packages\django\db\models\query.py", line 453, in create
    obj.save(force_insert=True, using=self.db)
  File "D:\django projects\exel_data\venv\lib\site-packages\django\db\models\base.py", line 726, in save
    self.save_base(using=using, force_insert=force_insert,
  File "D:\django projects\exel_data\venv\lib\site-packages\django\db\models\base.py", line 763, in save_base
    updated = self._save_table(
  File "D:\django projects\exel_data\venv\lib\site-packages\django\db\models\base.py", line 868, in _save_table
    results = self._do_insert(cls._base_manager, using, fields, returning_fields, raw)
  File "D:\django projects\exel_data\venv\lib\site-packages\django\db\models\base.py", line 906, in _do_insert
    return manager._insert(
  File "D:\django projects\exel_data\venv\lib\site-packages\django\db\models\manager.py", line 85, in manager_method
    return getattr(self.get_queryset(), name)(*args, **kwargs)
  File "D:\django projects\exel_data\venv\lib\site-packages\django\db\models\query.py", line 1270, in _insert
    return query.get_compiler(using=using).execute_sql(returning_fields)
  File "D:\django projects\exel_data\venv\lib\site-packages\django\db\models\sql\compiler.py", line 1415, in execute_sql
    for sql, params in self.as_sql():
  File "D:\django projects\exel_data\venv\lib\site-packages\django\db\models\sql\compiler.py", line 1358, in as_sql
    value_rows = [
  File "D:\django projects\exel_data\venv\lib\site-packages\django\db\models\sql\compiler.py", line 1359, in <listcomp>
    [self.prepare_value(field, self.pre_save_val(field, obj)) for field in fields]
  File "D:\django projects\exel_data\venv\lib\site-packages\django\db\models\sql\compiler.py", line 1359, in <listcomp>
    [self.prepare_value(field, self.pre_save_val(field, obj)) for field in fields]
  File "D:\django projects\exel_data\venv\lib\site-packages\django\db\models\sql\compiler.py", line 1300, in prepare_value
    value = field.get_db_prep_save(value, connection=self.connection)
  File "D:\django projects\exel_data\venv\lib\site-packages\django\db\models\fields\__init__.py", line 842, in get_db_prep_save
    return self.get_db_prep_value(value, connection=connection, prepared=False)
  File "D:\django projects\exel_data\venv\lib\site-packages\django\db\models\fields\__init__.py", line 1427, in get_db_prep_value
    value = self.get_prep_value(value)
  File "D:\django projects\exel_data\venv\lib\site-packages\django\db\models\fields\__init__.py", line 1406, in get_prep_value
    value = super().get_prep_value(value)
  File "D:\django projects\exel_data\venv\lib\site-packages\django\db\models\fields\__init__.py", line 1266, in get_prep_value
    return self.to_python(value)
  File "D:\django projects\exel_data\venv\lib\site-packages\django\db\models\fields\__init__.py", line 1367, in to_python
    parsed = parse_datetime(value)
  File "D:\django projects\exel_data\venv\lib\site-packages\django\utils\dateparse.py", line 107, in parse_datetime
    match = datetime_re.match(value)
TypeError: expected string or bytes-like object
INFO:django.utils.autoreload:D:\django projects\exel_data\project\models.py changed, reloading.
ERROR:django.request:Internal Server Error: /upload_excel
Traceback (most recent call last):
  File "D:\django projects\exel_data\venv\lib\site-packages\django\db\backends\utils.py", line 84, in _execute
    return self.cursor.execute(sql, params)
  File "D:\django projects\exel_data\venv\lib\site-packages\django\db\backends\mysql\base.py", line 73, in execute
    return self.cursor.execute(query, args)
  File "D:\django projects\exel_data\venv\lib\site-packages\MySQLdb\cursors.py", line 206, in execute
    res = self._query(query)
  File "D:\django projects\exel_data\venv\lib\site-packages\MySQLdb\cursors.py", line 319, in _query
    db.query(q)
  File "D:\django projects\exel_data\venv\lib\site-packages\MySQLdb\connections.py", line 254, in query
    _mysql.connection.query(self, query)
MySQLdb._exceptions.IntegrityError: (1062, "Duplicate entry 'ALI@gmail.com' for key 'project_person.project_person_email_82bd4bf0_uniq'")

The above exception was the direct cause of the following exception:

Traceback (most recent call last):
  File "D:\django projects\exel_data\venv\lib\site-packages\django\core\handlers\exception.py", line 47, in inner
    response = get_response(request)
  File "D:\django projects\exel_data\venv\lib\site-packages\django\core\handlers\base.py", line 181, in _get_response
    response = wrapped_callback(request, *callback_args, **callback_kwargs)
  File "D:\django projects\exel_data\project\views.py", line 29, in Import_excel_file
    save_obj(row)
  File "D:\django projects\exel_data\project\store_data.py", line 7, in save_obj
    Person.objects.create(first_name=row.first_name, last_name=row.last_name, email=row.email, created_at=now, job_title=row.job_title
  File "D:\django projects\exel_data\venv\lib\site-packages\django\db\models\manager.py", line 85, in manager_method
    return getattr(self.get_queryset(), name)(*args, **kwargs)
  File "D:\django projects\exel_data\venv\lib\site-packages\django\db\models\query.py", line 453, in create
    obj.save(force_insert=True, using=self.db)
  File "D:\django projects\exel_data\venv\lib\site-packages\django\db\models\base.py", line 726, in save
    self.save_base(using=using, force_insert=force_insert,
  File "D:\django projects\exel_data\venv\lib\site-packages\django\db\models\base.py", line 763, in save_base
    updated = self._save_table(
  File "D:\django projects\exel_data\venv\lib\site-packages\django\db\models\base.py", line 868, in _save_table
    results = self._do_insert(cls._base_manager, using, fields, returning_fields, raw)
  File "D:\django projects\exel_data\venv\lib\site-packages\django\db\models\base.py", line 906, in _do_insert
    return manager._insert(
  File "D:\django projects\exel_data\venv\lib\site-packages\django\db\models\manager.py", line 85, in manager_method
    return getattr(self.get_queryset(), name)(*args, **kwargs)
  File "D:\django projects\exel_data\venv\lib\site-packages\django\db\models\query.py", line 1270, in _insert
    return query.get_compiler(using=using).execute_sql(returning_fields)
  File "D:\django projects\exel_data\venv\lib\site-packages\django\db\models\sql\compiler.py", line 1416, in execute_sql
    cursor.execute(sql, params)
  File "D:\django projects\exel_data\venv\lib\site-packages\django\db\backends\utils.py", line 98, in execute
    return super().execute(sql, params)
  File "D:\django projects\exel_data\venv\lib\site-packages\django\db\backends\utils.py", line 66, in execute
    return self._execute_with_wrappers(sql, params, many=False, executor=self._execute)
  File "D:\django projects\exel_data\venv\lib\site-packages\django\db\backends\utils.py", line 75, in _execute_with_wrappers
    return executor(sql, params, many, context)
  File "D:\django projects\exel_data\venv\lib\site-packages\django\db\backends\utils.py", line 84, in _execute
    return self.cursor.execute(sql, params)
  File "D:\django projects\exel_data\venv\lib\site-packages\django\db\utils.py", line 90, in __exit__
    raise dj_exc_value.with_traceback(traceback) from exc_value
  File "D:\django projects\exel_data\venv\lib\site-packages\django\db\backends\utils.py", line 84, in _execute
    return self.cursor.execute(sql, params)
  File "D:\django projects\exel_data\venv\lib\site-packages\django\db\backends\mysql\base.py", line 73, in execute
    return self.cursor.execute(query, args)
  File "D:\django projects\exel_data\venv\lib\site-packages\MySQLdb\cursors.py", line 206, in execute
    res = self._query(query)
  File "D:\django projects\exel_data\venv\lib\site-packages\MySQLdb\cursors.py", line 319, in _query
    db.query(q)
  File "D:\django projects\exel_data\venv\lib\site-packages\MySQLdb\connections.py", line 254, in query
    _mysql.connection.query(self, query)
django.db.utils.IntegrityError: (1062, "Duplicate entry 'ALI@gmail.com' for key 'project_person.project_person_email_82bd4bf0_uniq'")
DEBUG:root:('Valid Row : 3', 'Invalid Row: 0')
INFO:django.utils.autoreload:D:\django projects\exel_data\CSV_data\update_emails_from_CSV_file.py changed, reloading.
INFO:django.utils.autoreload:D:\django projects\exel_data\CSV_data\update_emails_from_CSV_file.py changed, reloading.
DEBUG:root:('Valid Row : 3', 'Invalid Row: 0')
INFO:django.utils.autoreload:D:\django projects\exel_data\project\store_data.py changed, reloading.
INFO:django.utils.autoreload:D:\django projects\exel_data\project\store_data.py changed, reloading.
INFO:django.utils.autoreload:D:\django projects\exel_data\project\views.py changed, reloading.
ERROR:django.request:Internal Server Error: /upload_csv
Traceback (most recent call last):
  File "D:\django projects\exel_data\venv\lib\site-packages\django\core\handlers\exception.py", line 47, in inner
    response = get_response(request)
  File "D:\django projects\exel_data\venv\lib\site-packages\django\core\handlers\base.py", line 181, in _get_response
    response = wrapped_callback(request, *callback_args, **callback_kwargs)
  File "D:\django projects\exel_data\CSV_data\csv_file.py", line 26, in Import_csv_file
    save_obj(row)
TypeError: save_obj() missing 1 required positional argument: 'request'
ERROR:django.request:Internal Server Error: /upload_excel
Traceback (most recent call last):
  File "D:\django projects\exel_data\venv\lib\site-packages\django\utils\datastructures.py", line 76, in __getitem__
    list_ = super().__getitem__(key)
KeyError: ('file', None)

During handling of the above exception, another exception occurred:

Traceback (most recent call last):
  File "D:\django projects\exel_data\venv\lib\site-packages\django\core\handlers\exception.py", line 47, in inner
    response = get_response(request)
  File "D:\django projects\exel_data\venv\lib\site-packages\django\core\handlers\base.py", line 181, in _get_response
    response = wrapped_callback(request, *callback_args, **callback_kwargs)
  File "D:\django projects\exel_data\project\views.py", line 13, in Import_excel_file
    myfile = request.FILES['file', None]
  File "D:\django projects\exel_data\venv\lib\site-packages\django\utils\datastructures.py", line 78, in __getitem__
    raise MultiValueDictKeyError(key)
django.utils.datastructures.MultiValueDictKeyError: ('file', None)
INFO:django.utils.autoreload:D:\django projects\exel_data\project\views.py changed, reloading.
INFO:django.utils.autoreload:D:\django projects\exel_data\project\update_row_from_excel_file.py changed, reloading.
INFO:django.utils.autoreload:D:\django projects\exel_data\CSV_data\update_emails_from_CSV_file.py changed, reloading.
INFO:django.utils.autoreload:D:\django projects\exel_data\CSV_data\csv_file.py changed, reloading.
INFO:django.utils.autoreload:D:\django projects\exel_data\CSV_data\urls.py changed, reloading.
INFO:django.utils.autoreload:D:\django projects\exel_data\project\store_data.py changed, reloading.
INFO:django.utils.autoreload:D:\django projects\exel_data\project\store_data.py changed, reloading.
INFO:django.utils.autoreload:D:\django projects\exel_data\project\store_data.py changed, reloading.
ERROR:django.request:Internal Server Error: /upload_excel
Traceback (most recent call last):
  File "D:\django projects\exel_data\venv\lib\site-packages\django\core\handlers\exception.py", line 47, in inner
    response = get_response(request)
  File "D:\django projects\exel_data\venv\lib\site-packages\django\core\handlers\base.py", line 181, in _get_response
    response = wrapped_callback(request, *callback_args, **callback_kwargs)
  File "D:\django projects\exel_data\project\views.py", line 32, in Import_excel_file
    save_obj(row)
TypeError: save_obj() missing 1 required positional argument: 'request'
INFO:django.utils.autoreload:D:\django projects\exel_data\project\store_data.py changed, reloading.
ERROR:django.request:Internal Server Error: /upload_excel
Traceback (most recent call last):
  File "D:\django projects\exel_data\venv\lib\site-packages\django\db\backends\utils.py", line 84, in _execute
    return self.cursor.execute(sql, params)
  File "D:\django projects\exel_data\venv\lib\site-packages\django\db\backends\mysql\base.py", line 73, in execute
    return self.cursor.execute(query, args)
  File "D:\django projects\exel_data\venv\lib\site-packages\MySQLdb\cursors.py", line 206, in execute
    res = self._query(query)
  File "D:\django projects\exel_data\venv\lib\site-packages\MySQLdb\cursors.py", line 319, in _query
    db.query(q)
  File "D:\django projects\exel_data\venv\lib\site-packages\MySQLdb\connections.py", line 254, in query
    _mysql.connection.query(self, query)
MySQLdb._exceptions.IntegrityError: (1062, "Duplicate entry 'ALI123@gmail.com' for key 'project_person.project_person_email_82bd4bf0_uniq'")

The above exception was the direct cause of the following exception:

Traceback (most recent call last):
  File "D:\django projects\exel_data\venv\lib\site-packages\django\core\handlers\exception.py", line 47, in inner
    response = get_response(request)
  File "D:\django projects\exel_data\venv\lib\site-packages\django\core\handlers\base.py", line 181, in _get_response
    response = wrapped_callback(request, *callback_args, **callback_kwargs)
  File "D:\django projects\exel_data\project\views.py", line 32, in Import_excel_file
    save_obj(row)
  File "D:\django projects\exel_data\project\store_data.py", line 10, in save_obj
    Person.objects.create(first_name=row.first_name, last_name=row.last_name, email=row.email, created_at=now, job_title=row.job_title
  File "D:\django projects\exel_data\venv\lib\site-packages\django\db\models\manager.py", line 85, in manager_method
    return getattr(self.get_queryset(), name)(*args, **kwargs)
  File "D:\django projects\exel_data\venv\lib\site-packages\django\db\models\query.py", line 453, in create
    obj.save(force_insert=True, using=self.db)
  File "D:\django projects\exel_data\venv\lib\site-packages\django\db\models\base.py", line 726, in save
    self.save_base(using=using, force_insert=force_insert,
  File "D:\django projects\exel_data\venv\lib\site-packages\django\db\models\base.py", line 763, in save_base
    updated = self._save_table(
  File "D:\django projects\exel_data\venv\lib\site-packages\django\db\models\base.py", line 868, in _save_table
    results = self._do_insert(cls._base_manager, using, fields, returning_fields, raw)
  File "D:\django projects\exel_data\venv\lib\site-packages\django\db\models\base.py", line 906, in _do_insert
    return manager._insert(
  File "D:\django projects\exel_data\venv\lib\site-packages\django\db\models\manager.py", line 85, in manager_method
    return getattr(self.get_queryset(), name)(*args, **kwargs)
  File "D:\django projects\exel_data\venv\lib\site-packages\django\db\models\query.py", line 1270, in _insert
    return query.get_compiler(using=using).execute_sql(returning_fields)
  File "D:\django projects\exel_data\venv\lib\site-packages\django\db\models\sql\compiler.py", line 1416, in execute_sql
    cursor.execute(sql, params)
  File "D:\django projects\exel_data\venv\lib\site-packages\django\db\backends\utils.py", line 98, in execute
    return super().execute(sql, params)
  File "D:\django projects\exel_data\venv\lib\site-packages\django\db\backends\utils.py", line 66, in execute
    return self._execute_with_wrappers(sql, params, many=False, executor=self._execute)
  File "D:\django projects\exel_data\venv\lib\site-packages\django\db\backends\utils.py", line 75, in _execute_with_wrappers
    return executor(sql, params, many, context)
  File "D:\django projects\exel_data\venv\lib\site-packages\django\db\backends\utils.py", line 84, in _execute
    return self.cursor.execute(sql, params)
  File "D:\django projects\exel_data\venv\lib\site-packages\django\db\utils.py", line 90, in __exit__
    raise dj_exc_value.with_traceback(traceback) from exc_value
  File "D:\django projects\exel_data\venv\lib\site-packages\django\db\backends\utils.py", line 84, in _execute
    return self.cursor.execute(sql, params)
  File "D:\django projects\exel_data\venv\lib\site-packages\django\db\backends\mysql\base.py", line 73, in execute
    return self.cursor.execute(query, args)
  File "D:\django projects\exel_data\venv\lib\site-packages\MySQLdb\cursors.py", line 206, in execute
    res = self._query(query)
  File "D:\django projects\exel_data\venv\lib\site-packages\MySQLdb\cursors.py", line 319, in _query
    db.query(q)
  File "D:\django projects\exel_data\venv\lib\site-packages\MySQLdb\connections.py", line 254, in query
    _mysql.connection.query(self, query)
django.db.utils.IntegrityError: (1062, "Duplicate entry 'ALI123@gmail.com' for key 'project_person.project_person_email_82bd4bf0_uniq'")
INFO:django.utils.autoreload:D:\django projects\exel_data\project\store_data.py changed, reloading.
INFO:django.utils.autoreload:D:\django projects\exel_data\project\store_data.py changed, reloading.
INFO:django.utils.autoreload:D:\django projects\exel_data\project\store_data.py changed, reloading.
ERROR:django.request:Internal Server Error: /upload_excel
Traceback (most recent call last):
  File "D:\django projects\exel_data\venv\lib\site-packages\django\core\handlers\exception.py", line 47, in inner
    response = get_response(request)
  File "D:\django projects\exel_data\venv\lib\site-packages\django\core\handlers\base.py", line 181, in _get_response
    response = wrapped_callback(request, *callback_args, **callback_kwargs)
  File "D:\django projects\exel_data\project\views.py", line 32, in Import_excel_file
    save_obj(row)
TypeError: save_obj() missing 1 required positional argument: 'request'
INFO:django.utils.autoreload:D:\django projects\exel_data\project\store_data.py changed, reloading.
ERROR:django.request:Internal Server Error: /upload_excel
Traceback (most recent call last):
  File "D:\django projects\exel_data\venv\lib\site-packages\django\core\handlers\exception.py", line 47, in inner
    response = get_response(request)
  File "D:\django projects\exel_data\venv\lib\site-packages\django\core\handlers\base.py", line 181, in _get_response
    response = wrapped_callback(request, *callback_args, **callback_kwargs)
  File "D:\django projects\exel_data\project\views.py", line 32, in Import_excel_file
    save_obj(row)
TypeError: save_obj() missing 1 required positional argument: 'row'
INFO:django.utils.autoreload:D:\django projects\exel_data\project\store_data.py changed, reloading.
INFO:django.utils.autoreload:D:\django projects\exel_data\project\store_data.py changed, reloading.
ERROR:django.request:Internal Server Error: /upload_excel
Traceback (most recent call last):
  File "D:\django projects\exel_data\venv\lib\site-packages\django\core\handlers\exception.py", line 47, in inner
    response = get_response(request)
  File "D:\django projects\exel_data\venv\lib\site-packages\django\core\handlers\base.py", line 181, in _get_response
    response = wrapped_callback(request, *callback_args, **callback_kwargs)
  File "D:\django projects\exel_data\project\views.py", line 32, in Import_excel_file
    save_obj(row)
  File "D:\django projects\exel_data\project\store_data.py", line 12, in save_obj
    return render(request, 'messages.html', {"messages": "File Have Duplicate Emails"})
  File "D:\django projects\exel_data\venv\lib\site-packages\django\shortcuts.py", line 19, in render
    content = loader.render_to_string(template_name, context, request, using=using)
  File "D:\django projects\exel_data\venv\lib\site-packages\django\template\loader.py", line 62, in render_to_string
    return template.render(context, request)
  File "D:\django projects\exel_data\venv\lib\site-packages\django\template\backends\django.py", line 61, in render
    return self.template.render(context)
  File "D:\django projects\exel_data\venv\lib\site-packages\django\template\base.py", line 168, in render
    with context.bind_template(self):
  File "C:\Users\mohamed\AppData\Local\Programs\Python\Python39\lib\contextlib.py", line 117, in __enter__
    return next(self.gen)
  File "D:\django projects\exel_data\venv\lib\site-packages\django\template\context.py", line 244, in bind_template
    updates.update(processor(self.request))
  File "D:\django projects\exel_data\venv\lib\site-packages\django\template\context_processors.py", line 40, in debug
    if settings.DEBUG and request.META.get('REMOTE_ADDR') in settings.INTERNAL_IPS:
AttributeError: module 'urllib.request' has no attribute 'META'
INFO:django.utils.autoreload:D:\django projects\exel_data\project\store_data.py changed, reloading.
ERROR:django.request:Internal Server Error: /upload_excel
Traceback (most recent call last):
  File "D:\django projects\exel_data\venv\lib\site-packages\django\db\backends\utils.py", line 84, in _execute
    return self.cursor.execute(sql, params)
  File "D:\django projects\exel_data\venv\lib\site-packages\django\db\backends\mysql\base.py", line 73, in execute
    return self.cursor.execute(query, args)
  File "D:\django projects\exel_data\venv\lib\site-packages\MySQLdb\cursors.py", line 206, in execute
    res = self._query(query)
  File "D:\django projects\exel_data\venv\lib\site-packages\MySQLdb\cursors.py", line 319, in _query
    db.query(q)
  File "D:\django projects\exel_data\venv\lib\site-packages\MySQLdb\connections.py", line 254, in query
    _mysql.connection.query(self, query)
MySQLdb._exceptions.IntegrityError: (1062, "Duplicate entry 'ALI123@gmail.com' for key 'project_person.project_person_email_82bd4bf0_uniq'")

The above exception was the direct cause of the following exception:

Traceback (most recent call last):
  File "D:\django projects\exel_data\venv\lib\site-packages\django\core\handlers\exception.py", line 47, in inner
    response = get_response(request)
  File "D:\django projects\exel_data\venv\lib\site-packages\django\core\handlers\base.py", line 181, in _get_response
    response = wrapped_callback(request, *callback_args, **callback_kwargs)
  File "D:\django projects\exel_data\project\views.py", line 32, in Import_excel_file
    save_obj(row)
  File "D:\django projects\exel_data\project\store_data.py", line 14, in save_obj
    Person.objects.create(first_name=row.first_name, last_name=row.last_name, email=row.email, created_at=now, job_title=row.job_title
  File "D:\django projects\exel_data\venv\lib\site-packages\django\db\models\manager.py", line 85, in manager_method
    return getattr(self.get_queryset(), name)(*args, **kwargs)
  File "D:\django projects\exel_data\venv\lib\site-packages\django\db\models\query.py", line 453, in create
    obj.save(force_insert=True, using=self.db)
  File "D:\django projects\exel_data\venv\lib\site-packages\django\db\models\base.py", line 726, in save
    self.save_base(using=using, force_insert=force_insert,
  File "D:\django projects\exel_data\venv\lib\site-packages\django\db\models\base.py", line 763, in save_base
    updated = self._save_table(
  File "D:\django projects\exel_data\venv\lib\site-packages\django\db\models\base.py", line 868, in _save_table
    results = self._do_insert(cls._base_manager, using, fields, returning_fields, raw)
  File "D:\django projects\exel_data\venv\lib\site-packages\django\db\models\base.py", line 906, in _do_insert
    return manager._insert(
  File "D:\django projects\exel_data\venv\lib\site-packages\django\db\models\manager.py", line 85, in manager_method
    return getattr(self.get_queryset(), name)(*args, **kwargs)
  File "D:\django projects\exel_data\venv\lib\site-packages\django\db\models\query.py", line 1270, in _insert
    return query.get_compiler(using=using).execute_sql(returning_fields)
  File "D:\django projects\exel_data\venv\lib\site-packages\django\db\models\sql\compiler.py", line 1416, in execute_sql
    cursor.execute(sql, params)
  File "D:\django projects\exel_data\venv\lib\site-packages\django\db\backends\utils.py", line 98, in execute
    return super().execute(sql, params)
  File "D:\django projects\exel_data\venv\lib\site-packages\django\db\backends\utils.py", line 66, in execute
    return self._execute_with_wrappers(sql, params, many=False, executor=self._execute)
  File "D:\django projects\exel_data\venv\lib\site-packages\django\db\backends\utils.py", line 75, in _execute_with_wrappers
    return executor(sql, params, many, context)
  File "D:\django projects\exel_data\venv\lib\site-packages\django\db\backends\utils.py", line 84, in _execute
    return self.cursor.execute(sql, params)
  File "D:\django projects\exel_data\venv\lib\site-packages\django\db\utils.py", line 90, in __exit__
    raise dj_exc_value.with_traceback(traceback) from exc_value
  File "D:\django projects\exel_data\venv\lib\site-packages\django\db\backends\utils.py", line 84, in _execute
    return self.cursor.execute(sql, params)
  File "D:\django projects\exel_data\venv\lib\site-packages\django\db\backends\mysql\base.py", line 73, in execute
    return self.cursor.execute(query, args)
  File "D:\django projects\exel_data\venv\lib\site-packages\MySQLdb\cursors.py", line 206, in execute
    res = self._query(query)
  File "D:\django projects\exel_data\venv\lib\site-packages\MySQLdb\cursors.py", line 319, in _query
    db.query(q)
  File "D:\django projects\exel_data\venv\lib\site-packages\MySQLdb\connections.py", line 254, in query
    _mysql.connection.query(self, query)
django.db.utils.IntegrityError: (1062, "Duplicate entry 'ALI123@gmail.com' for key 'project_person.project_person_email_82bd4bf0_uniq'")
INFO:django.utils.autoreload:D:\django projects\exel_data\project\views.py changed, reloading.
ERROR:django.request:Internal Server Error: /upload_excel
Traceback (most recent call last):
  File "D:\django projects\exel_data\venv\lib\site-packages\django\db\backends\utils.py", line 84, in _execute
    return self.cursor.execute(sql, params)
  File "D:\django projects\exel_data\venv\lib\site-packages\django\db\backends\mysql\base.py", line 73, in execute
    return self.cursor.execute(query, args)
  File "D:\django projects\exel_data\venv\lib\site-packages\MySQLdb\cursors.py", line 206, in execute
    res = self._query(query)
  File "D:\django projects\exel_data\venv\lib\site-packages\MySQLdb\cursors.py", line 319, in _query
    db.query(q)
  File "D:\django projects\exel_data\venv\lib\site-packages\MySQLdb\connections.py", line 254, in query
    _mysql.connection.query(self, query)
MySQLdb._exceptions.IntegrityError: (1062, "Duplicate entry 'ALI123@gmail.com' for key 'project_person.project_person_email_82bd4bf0_uniq'")

The above exception was the direct cause of the following exception:

Traceback (most recent call last):
  File "D:\django projects\exel_data\venv\lib\site-packages\django\core\handlers\exception.py", line 47, in inner
    response = get_response(request)
  File "D:\django projects\exel_data\venv\lib\site-packages\django\core\handlers\base.py", line 181, in _get_response
    response = wrapped_callback(request, *callback_args, **callback_kwargs)
  File "D:\django projects\exel_data\project\views.py", line 32, in Import_excel_file
    save_obj(row, request)
  File "D:\django projects\exel_data\project\store_data.py", line 13, in save_obj
    Person.objects.create(first_name=row.first_name, last_name=row.last_name, email=row.email, created_at=now, job_title=row.job_title
  File "D:\django projects\exel_data\venv\lib\site-packages\django\db\models\manager.py", line 85, in manager_method
    return getattr(self.get_queryset(), name)(*args, **kwargs)
  File "D:\django projects\exel_data\venv\lib\site-packages\django\db\models\query.py", line 453, in create
    obj.save(force_insert=True, using=self.db)
  File "D:\django projects\exel_data\venv\lib\site-packages\django\db\models\base.py", line 726, in save
    self.save_base(using=using, force_insert=force_insert,
  File "D:\django projects\exel_data\venv\lib\site-packages\django\db\models\base.py", line 763, in save_base
    updated = self._save_table(
  File "D:\django projects\exel_data\venv\lib\site-packages\django\db\models\base.py", line 868, in _save_table
    results = self._do_insert(cls._base_manager, using, fields, returning_fields, raw)
  File "D:\django projects\exel_data\venv\lib\site-packages\django\db\models\base.py", line 906, in _do_insert
    return manager._insert(
  File "D:\django projects\exel_data\venv\lib\site-packages\django\db\models\manager.py", line 85, in manager_method
    return getattr(self.get_queryset(), name)(*args, **kwargs)
  File "D:\django projects\exel_data\venv\lib\site-packages\django\db\models\query.py", line 1270, in _insert
    return query.get_compiler(using=using).execute_sql(returning_fields)
  File "D:\django projects\exel_data\venv\lib\site-packages\django\db\models\sql\compiler.py", line 1416, in execute_sql
    cursor.execute(sql, params)
  File "D:\django projects\exel_data\venv\lib\site-packages\django\db\backends\utils.py", line 98, in execute
    return super().execute(sql, params)
  File "D:\django projects\exel_data\venv\lib\site-packages\django\db\backends\utils.py", line 66, in execute
    return self._execute_with_wrappers(sql, params, many=False, executor=self._execute)
  File "D:\django projects\exel_data\venv\lib\site-packages\django\db\backends\utils.py", line 75, in _execute_with_wrappers
    return executor(sql, params, many, context)
  File "D:\django projects\exel_data\venv\lib\site-packages\django\db\backends\utils.py", line 84, in _execute
    return self.cursor.execute(sql, params)
  File "D:\django projects\exel_data\venv\lib\site-packages\django\db\utils.py", line 90, in __exit__
    raise dj_exc_value.with_traceback(traceback) from exc_value
  File "D:\django projects\exel_data\venv\lib\site-packages\django\db\backends\utils.py", line 84, in _execute
    return self.cursor.execute(sql, params)
  File "D:\django projects\exel_data\venv\lib\site-packages\django\db\backends\mysql\base.py", line 73, in execute
    return self.cursor.execute(query, args)
  File "D:\django projects\exel_data\venv\lib\site-packages\MySQLdb\cursors.py", line 206, in execute
    res = self._query(query)
  File "D:\django projects\exel_data\venv\lib\site-packages\MySQLdb\cursors.py", line 319, in _query
    db.query(q)
  File "D:\django projects\exel_data\venv\lib\site-packages\MySQLdb\connections.py", line 254, in query
    _mysql.connection.query(self, query)
django.db.utils.IntegrityError: (1062, "Duplicate entry 'ALI123@gmail.com' for key 'project_person.project_person_email_82bd4bf0_uniq'")
INFO:django.utils.autoreload:D:\django projects\exel_data\project\store_data.py changed, reloading.
INFO:django.utils.autoreload:D:\django projects\exel_data\project\store_data.py changed, reloading.
INFO:django.utils.autoreload:D:\django projects\exel_data\project\store_data.py changed, reloading.
ERROR:django.request:Internal Server Error: /upload_excel
Traceback (most recent call last):
  File "D:\django projects\exel_data\venv\lib\site-packages\django\db\backends\utils.py", line 84, in _execute
    return self.cursor.execute(sql, params)
  File "D:\django projects\exel_data\venv\lib\site-packages\django\db\backends\mysql\base.py", line 73, in execute
    return self.cursor.execute(query, args)
  File "D:\django projects\exel_data\venv\lib\site-packages\MySQLdb\cursors.py", line 206, in execute
    res = self._query(query)
  File "D:\django projects\exel_data\venv\lib\site-packages\MySQLdb\cursors.py", line 319, in _query
    db.query(q)
  File "D:\django projects\exel_data\venv\lib\site-packages\MySQLdb\connections.py", line 254, in query
    _mysql.connection.query(self, query)
MySQLdb._exceptions.IntegrityError: (1062, "Duplicate entry 'ALI123@gmail.com' for key 'project_person.project_person_email_82bd4bf0_uniq'")

The above exception was the direct cause of the following exception:

Traceback (most recent call last):
  File "D:\django projects\exel_data\venv\lib\site-packages\django\core\handlers\exception.py", line 47, in inner
    response = get_response(request)
  File "D:\django projects\exel_data\venv\lib\site-packages\django\core\handlers\base.py", line 181, in _get_response
    response = wrapped_callback(request, *callback_args, **callback_kwargs)
  File "D:\django projects\exel_data\project\views.py", line 32, in Import_excel_file
    save_obj(row, request)
  File "D:\django projects\exel_data\project\store_data.py", line 13, in save_obj
    Person.objects.create(first_name=row.first_name, last_name=row.last_name, email=row.email, created_at=now,
  File "D:\django projects\exel_data\venv\lib\site-packages\django\db\models\manager.py", line 85, in manager_method
    return getattr(self.get_queryset(), name)(*args, **kwargs)
  File "D:\django projects\exel_data\venv\lib\site-packages\django\db\models\query.py", line 453, in create
    obj.save(force_insert=True, using=self.db)
  File "D:\django projects\exel_data\venv\lib\site-packages\django\db\models\base.py", line 726, in save
    self.save_base(using=using, force_insert=force_insert,
  File "D:\django projects\exel_data\venv\lib\site-packages\django\db\models\base.py", line 763, in save_base
    updated = self._save_table(
  File "D:\django projects\exel_data\venv\lib\site-packages\django\db\models\base.py", line 868, in _save_table
    results = self._do_insert(cls._base_manager, using, fields, returning_fields, raw)
  File "D:\django projects\exel_data\venv\lib\site-packages\django\db\models\base.py", line 906, in _do_insert
    return manager._insert(
  File "D:\django projects\exel_data\venv\lib\site-packages\django\db\models\manager.py", line 85, in manager_method
    return getattr(self.get_queryset(), name)(*args, **kwargs)
  File "D:\django projects\exel_data\venv\lib\site-packages\django\db\models\query.py", line 1270, in _insert
    return query.get_compiler(using=using).execute_sql(returning_fields)
  File "D:\django projects\exel_data\venv\lib\site-packages\django\db\models\sql\compiler.py", line 1416, in execute_sql
    cursor.execute(sql, params)
  File "D:\django projects\exel_data\venv\lib\site-packages\django\db\backends\utils.py", line 98, in execute
    return super().execute(sql, params)
  File "D:\django projects\exel_data\venv\lib\site-packages\django\db\backends\utils.py", line 66, in execute
    return self._execute_with_wrappers(sql, params, many=False, executor=self._execute)
  File "D:\django projects\exel_data\venv\lib\site-packages\django\db\backends\utils.py", line 75, in _execute_with_wrappers
    return executor(sql, params, many, context)
  File "D:\django projects\exel_data\venv\lib\site-packages\django\db\backends\utils.py", line 84, in _execute
    return self.cursor.execute(sql, params)
  File "D:\django projects\exel_data\venv\lib\site-packages\django\db\utils.py", line 90, in __exit__
    raise dj_exc_value.with_traceback(traceback) from exc_value
  File "D:\django projects\exel_data\venv\lib\site-packages\django\db\backends\utils.py", line 84, in _execute
    return self.cursor.execute(sql, params)
  File "D:\django projects\exel_data\venv\lib\site-packages\django\db\backends\mysql\base.py", line 73, in execute
    return self.cursor.execute(query, args)
  File "D:\django projects\exel_data\venv\lib\site-packages\MySQLdb\cursors.py", line 206, in execute
    res = self._query(query)
  File "D:\django projects\exel_data\venv\lib\site-packages\MySQLdb\cursors.py", line 319, in _query
    db.query(q)
  File "D:\django projects\exel_data\venv\lib\site-packages\MySQLdb\connections.py", line 254, in query
    _mysql.connection.query(self, query)
django.db.utils.IntegrityError: (1062, "Duplicate entry 'ALI123@gmail.com' for key 'project_person.project_person_email_82bd4bf0_uniq'")
INFO:django.utils.autoreload:D:\django projects\exel_data\project\store_data.py changed, reloading.
INFO:django.utils.autoreload:D:\django projects\exel_data\project\store_data.py changed, reloading.
INFO:django.utils.autoreload:D:\django projects\exel_data\project\views.py changed, reloading.
ERROR:django.request:Internal Server Error: /upload_excel
Traceback (most recent call last):
  File "D:\django projects\exel_data\venv\lib\site-packages\django\db\backends\utils.py", line 84, in _execute
    return self.cursor.execute(sql, params)
  File "D:\django projects\exel_data\venv\lib\site-packages\django\db\backends\mysql\base.py", line 73, in execute
    return self.cursor.execute(query, args)
  File "D:\django projects\exel_data\venv\lib\site-packages\MySQLdb\cursors.py", line 206, in execute
    res = self._query(query)
  File "D:\django projects\exel_data\venv\lib\site-packages\MySQLdb\cursors.py", line 319, in _query
    db.query(q)
  File "D:\django projects\exel_data\venv\lib\site-packages\MySQLdb\connections.py", line 254, in query
    _mysql.connection.query(self, query)
MySQLdb._exceptions.IntegrityError: (1062, "Duplicate entry 'ALI123@gmail.com' for key 'project_person.project_person_email_82bd4bf0_uniq'")

The above exception was the direct cause of the following exception:

Traceback (most recent call last):
  File "D:\django projects\exel_data\venv\lib\site-packages\django\core\handlers\exception.py", line 47, in inner
    response = get_response(request)
  File "D:\django projects\exel_data\venv\lib\site-packages\django\core\handlers\base.py", line 181, in _get_response
    response = wrapped_callback(request, *callback_args, **callback_kwargs)
  File "D:\django projects\exel_data\project\views.py", line 37, in Import_excel_file
    save_obj(row, request)
  File "D:\django projects\exel_data\project\store_data.py", line 8, in save_obj
    Person.objects.create(first_name=row.first_name, last_name=row.last_name, email=row.email, created_at=now,
  File "D:\django projects\exel_data\venv\lib\site-packages\django\db\models\manager.py", line 85, in manager_method
    return getattr(self.get_queryset(), name)(*args, **kwargs)
  File "D:\django projects\exel_data\venv\lib\site-packages\django\db\models\query.py", line 453, in create
    obj.save(force_insert=True, using=self.db)
  File "D:\django projects\exel_data\venv\lib\site-packages\django\db\models\base.py", line 726, in save
    self.save_base(using=using, force_insert=force_insert,
  File "D:\django projects\exel_data\venv\lib\site-packages\django\db\models\base.py", line 763, in save_base
    updated = self._save_table(
  File "D:\django projects\exel_data\venv\lib\site-packages\django\db\models\base.py", line 868, in _save_table
    results = self._do_insert(cls._base_manager, using, fields, returning_fields, raw)
  File "D:\django projects\exel_data\venv\lib\site-packages\django\db\models\base.py", line 906, in _do_insert
    return manager._insert(
  File "D:\django projects\exel_data\venv\lib\site-packages\django\db\models\manager.py", line 85, in manager_method
    return getattr(self.get_queryset(), name)(*args, **kwargs)
  File "D:\django projects\exel_data\venv\lib\site-packages\django\db\models\query.py", line 1270, in _insert
    return query.get_compiler(using=using).execute_sql(returning_fields)
  File "D:\django projects\exel_data\venv\lib\site-packages\django\db\models\sql\compiler.py", line 1416, in execute_sql
    cursor.execute(sql, params)
  File "D:\django projects\exel_data\venv\lib\site-packages\django\db\backends\utils.py", line 98, in execute
    return super().execute(sql, params)
  File "D:\django projects\exel_data\venv\lib\site-packages\django\db\backends\utils.py", line 66, in execute
    return self._execute_with_wrappers(sql, params, many=False, executor=self._execute)
  File "D:\django projects\exel_data\venv\lib\site-packages\django\db\backends\utils.py", line 75, in _execute_with_wrappers
    return executor(sql, params, many, context)
  File "D:\django projects\exel_data\venv\lib\site-packages\django\db\backends\utils.py", line 84, in _execute
    return self.cursor.execute(sql, params)
  File "D:\django projects\exel_data\venv\lib\site-packages\django\db\utils.py", line 90, in __exit__
    raise dj_exc_value.with_traceback(traceback) from exc_value
  File "D:\django projects\exel_data\venv\lib\site-packages\django\db\backends\utils.py", line 84, in _execute
    return self.cursor.execute(sql, params)
  File "D:\django projects\exel_data\venv\lib\site-packages\django\db\backends\mysql\base.py", line 73, in execute
    return self.cursor.execute(query, args)
  File "D:\django projects\exel_data\venv\lib\site-packages\MySQLdb\cursors.py", line 206, in execute
    res = self._query(query)
  File "D:\django projects\exel_data\venv\lib\site-packages\MySQLdb\cursors.py", line 319, in _query
    db.query(q)
  File "D:\django projects\exel_data\venv\lib\site-packages\MySQLdb\connections.py", line 254, in query
    _mysql.connection.query(self, query)
django.db.utils.IntegrityError: (1062, "Duplicate entry 'ALI123@gmail.com' for key 'project_person.project_person_email_82bd4bf0_uniq'")
INFO:django.utils.autoreload:D:\django projects\exel_data\project\views.py changed, reloading.
INFO:django.utils.autoreload:D:\django projects\exel_data\project\views.py changed, reloading.
ERROR:django.request:Internal Server Error: /update_excel
Traceback (most recent call last):
  File "D:\django projects\exel_data\venv\lib\site-packages\django\core\handlers\exception.py", line 47, in inner
    response = get_response(request)
  File "D:\django projects\exel_data\venv\lib\site-packages\django\core\handlers\base.py", line 181, in _get_response
    response = wrapped_callback(request, *callback_args, **callback_kwargs)
  File "D:\django projects\exel_data\project\update_row_from_excel_file.py", line 36, in update_email_excel_file
    get_row.save()
  File "D:\django projects\exel_data\venv\lib\site-packages\django\db\models\base.py", line 726, in save
    self.save_base(using=using, force_insert=force_insert,
  File "D:\django projects\exel_data\venv\lib\site-packages\django\db\models\base.py", line 763, in save_base
    updated = self._save_table(
  File "D:\django projects\exel_data\venv\lib\site-packages\django\db\models\base.py", line 845, in _save_table
    updated = self._do_update(base_qs, using, pk_val, values, update_fields,
  File "D:\django projects\exel_data\venv\lib\site-packages\django\db\models\base.py", line 899, in _do_update
    return filtered._update(values) > 0
  File "D:\django projects\exel_data\venv\lib\site-packages\django\db\models\query.py", line 802, in _update
    return query.get_compiler(self.db).execute_sql(CURSOR)
  File "D:\django projects\exel_data\venv\lib\site-packages\django\db\models\sql\compiler.py", line 1559, in execute_sql
    cursor = super().execute_sql(result_type)
  File "D:\django projects\exel_data\venv\lib\site-packages\django\db\models\sql\compiler.py", line 1162, in execute_sql
    sql, params = self.as_sql()
  File "D:\django projects\exel_data\venv\lib\site-packages\django\db\backends\mysql\compiler.py", line 44, in as_sql
    update_query, update_params = super().as_sql()
  File "D:\django projects\exel_data\venv\lib\site-packages\django\db\models\sql\compiler.py", line 1525, in as_sql
    val = field.get_db_prep_save(val, connection=self.connection)
  File "D:\django projects\exel_data\venv\lib\site-packages\django\db\models\fields\__init__.py", line 842, in get_db_prep_save
    return self.get_db_prep_value(value, connection=connection, prepared=False)
  File "D:\django projects\exel_data\venv\lib\site-packages\django\db\models\fields\__init__.py", line 1427, in get_db_prep_value
    value = self.get_prep_value(value)
  File "D:\django projects\exel_data\venv\lib\site-packages\django\db\models\fields\__init__.py", line 1406, in get_prep_value
    value = super().get_prep_value(value)
  File "D:\django projects\exel_data\venv\lib\site-packages\django\db\models\fields\__init__.py", line 1266, in get_prep_value
    return self.to_python(value)
  File "D:\django projects\exel_data\venv\lib\site-packages\django\db\models\fields\__init__.py", line 1367, in to_python
    parsed = parse_datetime(value)
  File "D:\django projects\exel_data\venv\lib\site-packages\django\utils\dateparse.py", line 107, in parse_datetime
    match = datetime_re.match(value)
TypeError: expected string or bytes-like object
INFO:django.utils.autoreload:D:\django projects\exel_data\project\update_row_from_excel_file.py changed, reloading.
DEBUG:root:('Updates Row : 3', 'Invalid Row: 0')
WARNING:django.request:Not Found: /upload_file
DEBUG:root:('Updates Row : 3', 'Invalid Row: 0')
INFO:django.utils.autoreload:D:\django projects\exel_data\project\update_row_from_excel_file.py changed, reloading.
DEBUG:root:('Updates Row : 3', 'Invalid Row: 0')
DEBUG:root:('Updates Row : 3', 'Invalid Row: 0')
INFO:django.utils.autoreload:D:\django projects\exel_data\project\views.py changed, reloading.
INFO:django.utils.autoreload:D:\django projects\exel_data\project\views.py changed, reloading.
INFO:django.utils.autoreload:D:\django projects\exel_data\project\views.py changed, reloading.
ERROR:django.request:Internal Server Error: /upload_excel
Traceback (most recent call last):
  File "D:\django projects\exel_data\venv\lib\site-packages\django\core\handlers\exception.py", line 47, in inner
    response = get_response(request)
  File "D:\django projects\exel_data\venv\lib\site-packages\django\core\handlers\base.py", line 181, in _get_response
    response = wrapped_callback(request, *callback_args, **callback_kwargs)
  File "D:\django projects\exel_data\project\views.py", line 39, in Import_excel_file
    save_obj(row)
TypeError: save_obj() missing 1 required positional argument: 'request'
INFO:django.utils.autoreload:D:\django projects\exel_data\project\store_data.py changed, reloading.
DEBUG:root:('Valid Row : 3', 'Invalid Row: 0')
INFO:django.utils.autoreload:D:\django projects\exel_data\project\models.py changed, reloading.
INFO:django.utils.autoreload:D:\django projects\exel_data\CSV_data\csv_file.py changed, reloading.
INFO:django.utils.autoreload:D:\django projects\exel_data\CSV_data\csv_file.py changed, reloading.
INFO:django.utils.autoreload:D:\django projects\exel_data\CSV_data\csv_file.py changed, reloading.
INFO:django.utils.autoreload:D:\django projects\exel_data\CSV_data\urls.py changed, reloading.
DEBUG:root:('Valid Row : 3', 'Invalid Row: 0')
ERROR:django.request:Internal Server Error: /update_csv
Traceback (most recent call last):
  File "D:\django projects\exel_data\venv\lib\site-packages\django\core\handlers\exception.py", line 47, in inner
    response = get_response(request)
  File "D:\django projects\exel_data\venv\lib\site-packages\django\core\handlers\base.py", line 181, in _get_response
    response = wrapped_callback(request, *callback_args, **callback_kwargs)
  File "D:\django projects\exel_data\CSV_data\update_CSV.py", line 21, in update_excel_file
    df = pd.read_csv(myfile)
  File "D:\django projects\exel_data\venv\lib\site-packages\pandas\util\_decorators.py", line 311, in wrapper
    return func(*args, **kwargs)
  File "D:\django projects\exel_data\venv\lib\site-packages\pandas\io\parsers\readers.py", line 586, in read_csv
    return _read(filepath_or_buffer, kwds)
  File "D:\django projects\exel_data\venv\lib\site-packages\pandas\io\parsers\readers.py", line 488, in _read
    return parser.read(nrows)
  File "D:\django projects\exel_data\venv\lib\site-packages\pandas\io\parsers\readers.py", line 1047, in read
    index, columns, col_dict = self._engine.read(nrows)
  File "D:\django projects\exel_data\venv\lib\site-packages\pandas\io\parsers\c_parser_wrapper.py", line 223, in read
    chunks = self._reader.read_low_memory(nrows)
  File "pandas\_libs\parsers.pyx", line 801, in pandas._libs.parsers.TextReader.read_low_memory
  File "pandas\_libs\parsers.pyx", line 857, in pandas._libs.parsers.TextReader._read_rows
  File "pandas\_libs\parsers.pyx", line 843, in pandas._libs.parsers.TextReader._tokenize_rows
  File "pandas\_libs\parsers.pyx", line 1925, in pandas._libs.parsers.raise_parser_error
pandas.errors.ParserError: Error tokenizing data. C error: Expected 1 fields in line 3, saw 2

DEBUG:root:('Valid Row : 3', 'Invalid Row: 0')
DEBUG:root:('Updates Row : 3', 'Invalid Row: 0')
INFO:django.utils.autoreload:D:\django projects\exel_data\project\update_row_from_excel_file.py changed, reloading.
DEBUG:root:('Index: 4', 'First Name: nan', 'Last Name: nan', 'Email: nan')
DEBUG:root:('Index: 4', 'First Name: nan', 'Last Name: nan', 'Email: nan')
ERROR:django.request:Internal Server Error: /update_excel
Traceback (most recent call last):
  File "D:\django projects\exel_data\venv\lib\site-packages\django\core\handlers\exception.py", line 47, in inner
    response = get_response(request)
  File "D:\django projects\exel_data\venv\lib\site-packages\django\core\handlers\base.py", line 181, in _get_response
    response = wrapped_callback(request, *callback_args, **callback_kwargs)
  File "D:\django projects\exel_data\project\update_row_from_excel_file.py", line 39, in update_email_excel_file
    elif get_row.email == row.email:
AttributeError: 'NoneType' object has no attribute 'email'
INFO:django.utils.autoreload:D:\django projects\exel_data\project\update_row_from_excel_file.py changed, reloading.
DEBUG:root:('Index: 4', 'First Name: nan', 'Last Name: nan', 'Email: nan')
DEBUG:root:('Updates Row : 4', 'Invalid Row: 1')
DEBUG:root:('Index: 4', 'First Name: nan', 'Last Name: nan', 'Email: nan')
DEBUG:root:('Updates Row : 5', 'Invalid Row: 1')
INFO:django.utils.autoreload:D:\django projects\exel_data\project\update_row_from_excel_file.py changed, reloading.
INFO:django.utils.autoreload:D:\django projects\exel_data\project\views.py changed, reloading.
DEBUG:root:('Index: 4', 'First Name: nan', 'Last Name: nan', 'Email: nan')
DEBUG:root:('Valid Row : 5', 'Invalid Row: 1')
INFO:django.utils.autoreload:D:\django projects\exel_data\project\views.py changed, reloading.
INFO:django.utils.autoreload:D:\django projects\exel_data\project\views.py changed, reloading.
DEBUG:root:('Valid Row : 3', 'Invalid Row: 0')
INFO:django.utils.autoreload:D:\django projects\exel_data\exel_data\settings.py changed, reloading.
INFO:django.utils.autoreload:D:\django projects\exel_data\project\views.py changed, reloading.
INFO:django.utils.autoreload:D:\django projects\exel_data\project\urls.py changed, reloading.
DEBUG:root:('Index: 4', 'First Name: nan', 'Last Name: nan', 'Email: nan')
DEBUG:root:('Valid Row : 5', 'Invalid Row: 1')
WARNING:django.request:Not Found: /upload_excel
INFO:django.utils.autoreload:D:\django projects\exel_data\exel_data\urls.py changed, reloading.
ERROR:django.request:Internal Server Error: /upload_file
Traceback (most recent call last):
  File "D:\django projects\exel_data\venv\lib\site-packages\django\core\handlers\exception.py", line 47, in inner
    response = get_response(request)
  File "D:\django projects\exel_data\venv\lib\site-packages\django\core\handlers\base.py", line 181, in _get_response
    response = wrapped_callback(request, *callback_args, **callback_kwargs)
  File "D:\django projects\exel_data\project\views.py", line 60, in Import_file
    return render(request, 'upload_excel_file.html')
  File "D:\django projects\exel_data\venv\lib\site-packages\django\shortcuts.py", line 19, in render
    content = loader.render_to_string(template_name, context, request, using=using)
  File "D:\django projects\exel_data\venv\lib\site-packages\django\template\loader.py", line 62, in render_to_string
    return template.render(context, request)
  File "D:\django projects\exel_data\venv\lib\site-packages\django\template\backends\django.py", line 61, in render
    return self.template.render(context)
  File "D:\django projects\exel_data\venv\lib\site-packages\django\template\base.py", line 170, in render
    return self._render(context)
  File "D:\django projects\exel_data\venv\lib\site-packages\django\template\base.py", line 162, in _render
    return self.nodelist.render(context)
  File "D:\django projects\exel_data\venv\lib\site-packages\django\template\base.py", line 938, in render
    bit = node.render_annotated(context)
  File "D:\django projects\exel_data\venv\lib\site-packages\django\template\base.py", line 905, in render_annotated
    return self.render(context)
  File "D:\django projects\exel_data\venv\lib\site-packages\django\template\defaulttags.py", line 446, in render
    url = reverse(view_name, args=args, kwargs=kwargs, current_app=current_app)
  File "D:\django projects\exel_data\venv\lib\site-packages\django\urls\base.py", line 86, in reverse
    return resolver._reverse_with_prefix(view, prefix, *args, **kwargs)
  File "D:\django projects\exel_data\venv\lib\site-packages\django\urls\resolvers.py", line 694, in _reverse_with_prefix
    raise NoReverseMatch(msg)
django.urls.exceptions.NoReverseMatch: Reverse for 'home' not found. 'home' is not a valid view function or pattern name.
ERROR:django.request:Internal Server Error: /upload_file
Traceback (most recent call last):
  File "D:\django projects\exel_data\venv\lib\site-packages\django\utils\datastructures.py", line 76, in __getitem__
    list_ = super().__getitem__(key)
KeyError: 'file'

During handling of the above exception, another exception occurred:

Traceback (most recent call last):
  File "D:\django projects\exel_data\venv\lib\site-packages\django\core\handlers\exception.py", line 47, in inner
    response = get_response(request)
  File "D:\django projects\exel_data\venv\lib\site-packages\django\core\handlers\base.py", line 181, in _get_response
    response = wrapped_callback(request, *callback_args, **callback_kwargs)
  File "D:\django projects\exel_data\project\views.py", line 14, in Import_file
    myfile = request.FILES['file']
  File "D:\django projects\exel_data\venv\lib\site-packages\django\utils\datastructures.py", line 78, in __getitem__
    raise MultiValueDictKeyError(key)
django.utils.datastructures.MultiValueDictKeyError: 'file'
DEBUG:root:('Valid Row : 3', 'Invalid Row: 0')
INFO:django.utils.autoreload:D:\django projects\exel_data\project\views.py changed, reloading.
DEBUG:root:('Index: 4', 'First Name: nan', 'Last Name: nan', 'Email: nan')
DEBUG:root:('Valid Row : 5', 'Invalid Row: 1')
