ERROR:django.request:Internal Server Error: /update_email
Traceback (most recent call last):
  File "D:\django projects\exel_data\venv\lib\site-packages\django\utils\datastructures.py", line 76, in __getitem__
    list_ = super().__getitem__(key)
KeyError: 'file'

During handling of the above exception, another exception occurred:

Traceback (most recent call last):
  File "D:\django projects\exel_data\venv\lib\site-packages\django\core\handlers\exception.py", line 47, in inner
    response = get_response(request)
  File "D:\django projects\exel_data\venv\lib\site-packages\django\core\handlers\base.py", line 181, in _get_response
    response = wrapped_callback(request, *callback_args, **callback_kwargs)
  File "D:\django projects\exel_data\project\email.py", line 12, in update_email
    myfile = request.FILES['file']
  File "D:\django projects\exel_data\venv\lib\site-packages\django\utils\datastructures.py", line 78, in __getitem__
    raise MultiValueDictKeyError(key)
django.utils.datastructures.MultiValueDictKeyError: 'file'
INFO:django.utils.autoreload:D:\django projects\exel_data\project\email.py changed, reloading.
INFO:django.utils.autoreload:D:\django projects\exel_data\project\email.py changed, reloading.
ERROR:django.request:Internal Server Error: /update_email
Traceback (most recent call last):
  File "D:\django projects\exel_data\venv\lib\site-packages\django\db\backends\utils.py", line 84, in _execute
    return self.cursor.execute(sql, params)
  File "D:\django projects\exel_data\venv\lib\site-packages\django\db\backends\mysql\base.py", line 73, in execute
    return self.cursor.execute(query, args)
  File "D:\django projects\exel_data\venv\lib\site-packages\MySQLdb\cursors.py", line 206, in execute
    res = self._query(query)
  File "D:\django projects\exel_data\venv\lib\site-packages\MySQLdb\cursors.py", line 319, in _query
    db.query(q)
  File "D:\django projects\exel_data\venv\lib\site-packages\MySQLdb\connections.py", line 254, in query
    _mysql.connection.query(self, query)
MySQLdb._exceptions.IntegrityError: (1062, "Duplicate entry 'mo@gmail.com' for key 'project_person.project_person_email_82bd4bf0_uniq'")

The above exception was the direct cause of the following exception:

Traceback (most recent call last):
  File "D:\django projects\exel_data\venv\lib\site-packages\django\core\handlers\exception.py", line 47, in inner
    response = get_response(request)
  File "D:\django projects\exel_data\venv\lib\site-packages\django\core\handlers\base.py", line 181, in _get_response
    response = wrapped_callback(request, *callback_args, **callback_kwargs)
  File "D:\django projects\exel_data\project\email.py", line 33, in update_email
    check_index.save()
  File "D:\django projects\exel_data\venv\lib\site-packages\django\db\models\base.py", line 726, in save
    self.save_base(using=using, force_insert=force_insert,
  File "D:\django projects\exel_data\venv\lib\site-packages\django\db\models\base.py", line 763, in save_base
    updated = self._save_table(
  File "D:\django projects\exel_data\venv\lib\site-packages\django\db\models\base.py", line 845, in _save_table
    updated = self._do_update(base_qs, using, pk_val, values, update_fields,
  File "D:\django projects\exel_data\venv\lib\site-packages\django\db\models\base.py", line 899, in _do_update
    return filtered._update(values) > 0
  File "D:\django projects\exel_data\venv\lib\site-packages\django\db\models\query.py", line 802, in _update
    return query.get_compiler(self.db).execute_sql(CURSOR)
  File "D:\django projects\exel_data\venv\lib\site-packages\django\db\models\sql\compiler.py", line 1559, in execute_sql
    cursor = super().execute_sql(result_type)
  File "D:\django projects\exel_data\venv\lib\site-packages\django\db\models\sql\compiler.py", line 1175, in execute_sql
    cursor.execute(sql, params)
  File "D:\django projects\exel_data\venv\lib\site-packages\django\db\backends\utils.py", line 98, in execute
    return super().execute(sql, params)
  File "D:\django projects\exel_data\venv\lib\site-packages\django\db\backends\utils.py", line 66, in execute
    return self._execute_with_wrappers(sql, params, many=False, executor=self._execute)
  File "D:\django projects\exel_data\venv\lib\site-packages\django\db\backends\utils.py", line 75, in _execute_with_wrappers
    return executor(sql, params, many, context)
  File "D:\django projects\exel_data\venv\lib\site-packages\django\db\backends\utils.py", line 84, in _execute
    return self.cursor.execute(sql, params)
  File "D:\django projects\exel_data\venv\lib\site-packages\django\db\utils.py", line 90, in __exit__
    raise dj_exc_value.with_traceback(traceback) from exc_value
  File "D:\django projects\exel_data\venv\lib\site-packages\django\db\backends\utils.py", line 84, in _execute
    return self.cursor.execute(sql, params)
  File "D:\django projects\exel_data\venv\lib\site-packages\django\db\backends\mysql\base.py", line 73, in execute
    return self.cursor.execute(query, args)
  File "D:\django projects\exel_data\venv\lib\site-packages\MySQLdb\cursors.py", line 206, in execute
    res = self._query(query)
  File "D:\django projects\exel_data\venv\lib\site-packages\MySQLdb\cursors.py", line 319, in _query
    db.query(q)
  File "D:\django projects\exel_data\venv\lib\site-packages\MySQLdb\connections.py", line 254, in query
    _mysql.connection.query(self, query)
django.db.utils.IntegrityError: (1062, "Duplicate entry 'mo@gmail.com' for key 'project_person.project_person_email_82bd4bf0_uniq'")
INFO:django.utils.autoreload:D:\django projects\exel_data\exel_data\urls.py changed, reloading.
INFO:django.utils.autoreload:D:\django projects\exel_data\project\update_emails_from_excel_file.py changed, reloading.
INFO:django.utils.autoreload:D:\django projects\exel_data\exel_data\settings.py changed, reloading.
INFO:django.utils.autoreload:D:\django projects\exel_data\exel_data\urls.py changed, reloading.
