ERROR:django.request:Internal Server Error: /update_email
Traceback (most recent call last):
  File "D:\django projects\exel_data\venv\lib\site-packages\django\utils\datastructures.py", line 76, in __getitem__
    list_ = super().__getitem__(key)
KeyError: 'file'

During handling of the above exception, another exception occurred:

Traceback (most recent call last):
  File "D:\django projects\exel_data\venv\lib\site-packages\django\core\handlers\exception.py", line 47, in inner
    response = get_response(request)
  File "D:\django projects\exel_data\venv\lib\site-packages\django\core\handlers\base.py", line 181, in _get_response
    response = wrapped_callback(request, *callback_args, **callback_kwargs)
  File "D:\django projects\exel_data\project\email.py", line 12, in update_email
    myfile = request.FILES['file']
  File "D:\django projects\exel_data\venv\lib\site-packages\django\utils\datastructures.py", line 78, in __getitem__
    raise MultiValueDictKeyError(key)
django.utils.datastructures.MultiValueDictKeyError: 'file'
INFO:django.utils.autoreload:D:\django projects\exel_data\project\email.py changed, reloading.
INFO:django.utils.autoreload:D:\django projects\exel_data\project\email.py changed, reloading.
ERROR:django.request:Internal Server Error: /update_email
Traceback (most recent call last):
  File "D:\django projects\exel_data\venv\lib\site-packages\django\db\backends\utils.py", line 84, in _execute
    return self.cursor.execute(sql, params)
  File "D:\django projects\exel_data\venv\lib\site-packages\django\db\backends\mysql\base.py", line 73, in execute
    return self.cursor.execute(query, args)
  File "D:\django projects\exel_data\venv\lib\site-packages\MySQLdb\cursors.py", line 206, in execute
    res = self._query(query)
  File "D:\django projects\exel_data\venv\lib\site-packages\MySQLdb\cursors.py", line 319, in _query
    db.query(q)
  File "D:\django projects\exel_data\venv\lib\site-packages\MySQLdb\connections.py", line 254, in query
    _mysql.connection.query(self, query)
MySQLdb._exceptions.IntegrityError: (1062, "Duplicate entry 'mo@gmail.com' for key 'project_person.project_person_email_82bd4bf0_uniq'")

The above exception was the direct cause of the following exception:

Traceback (most recent call last):
  File "D:\django projects\exel_data\venv\lib\site-packages\django\core\handlers\exception.py", line 47, in inner
    response = get_response(request)
  File "D:\django projects\exel_data\venv\lib\site-packages\django\core\handlers\base.py", line 181, in _get_response
    response = wrapped_callback(request, *callback_args, **callback_kwargs)
  File "D:\django projects\exel_data\project\email.py", line 33, in update_email
    check_index.save()
  File "D:\django projects\exel_data\venv\lib\site-packages\django\db\models\base.py", line 726, in save
    self.save_base(using=using, force_insert=force_insert,
  File "D:\django projects\exel_data\venv\lib\site-packages\django\db\models\base.py", line 763, in save_base
    updated = self._save_table(
  File "D:\django projects\exel_data\venv\lib\site-packages\django\db\models\base.py", line 845, in _save_table
    updated = self._do_update(base_qs, using, pk_val, values, update_fields,
  File "D:\django projects\exel_data\venv\lib\site-packages\django\db\models\base.py", line 899, in _do_update
    return filtered._update(values) > 0
  File "D:\django projects\exel_data\venv\lib\site-packages\django\db\models\query.py", line 802, in _update
    return query.get_compiler(self.db).execute_sql(CURSOR)
  File "D:\django projects\exel_data\venv\lib\site-packages\django\db\models\sql\compiler.py", line 1559, in execute_sql
    cursor = super().execute_sql(result_type)
  File "D:\django projects\exel_data\venv\lib\site-packages\django\db\models\sql\compiler.py", line 1175, in execute_sql
    cursor.execute(sql, params)
  File "D:\django projects\exel_data\venv\lib\site-packages\django\db\backends\utils.py", line 98, in execute
    return super().execute(sql, params)
  File "D:\django projects\exel_data\venv\lib\site-packages\django\db\backends\utils.py", line 66, in execute
    return self._execute_with_wrappers(sql, params, many=False, executor=self._execute)
  File "D:\django projects\exel_data\venv\lib\site-packages\django\db\backends\utils.py", line 75, in _execute_with_wrappers
    return executor(sql, params, many, context)
  File "D:\django projects\exel_data\venv\lib\site-packages\django\db\backends\utils.py", line 84, in _execute
    return self.cursor.execute(sql, params)
  File "D:\django projects\exel_data\venv\lib\site-packages\django\db\utils.py", line 90, in __exit__
    raise dj_exc_value.with_traceback(traceback) from exc_value
  File "D:\django projects\exel_data\venv\lib\site-packages\django\db\backends\utils.py", line 84, in _execute
    return self.cursor.execute(sql, params)
  File "D:\django projects\exel_data\venv\lib\site-packages\django\db\backends\mysql\base.py", line 73, in execute
    return self.cursor.execute(query, args)
  File "D:\django projects\exel_data\venv\lib\site-packages\MySQLdb\cursors.py", line 206, in execute
    res = self._query(query)
  File "D:\django projects\exel_data\venv\lib\site-packages\MySQLdb\cursors.py", line 319, in _query
    db.query(q)
  File "D:\django projects\exel_data\venv\lib\site-packages\MySQLdb\connections.py", line 254, in query
    _mysql.connection.query(self, query)
django.db.utils.IntegrityError: (1062, "Duplicate entry 'mo@gmail.com' for key 'project_person.project_person_email_82bd4bf0_uniq'")
INFO:django.utils.autoreload:D:\django projects\exel_data\exel_data\urls.py changed, reloading.
INFO:django.utils.autoreload:D:\django projects\exel_data\project\update_emails_from_excel_file.py changed, reloading.
INFO:django.utils.autoreload:D:\django projects\exel_data\exel_data\settings.py changed, reloading.
INFO:django.utils.autoreload:D:\django projects\exel_data\exel_data\urls.py changed, reloading.
DEBUG:root:('Index: 4', 'First Name: nan', 'Last Name: n', 'Email: n@gmail.com')
DEBUG:root:('Updates Row : 6', 'Invalid Row: 1')
INFO:django.utils.autoreload:D:\django projects\exel_data\project\update_emails_from_excel_file.py changed, reloading.
INFO:django.utils.autoreload:D:\django projects\exel_data\project\models.py changed, reloading.
INFO:django.utils.autoreload:D:\django projects\exel_data\project\models.py changed, reloading.
INFO:django.utils.autoreload:D:\django projects\exel_data\project\views.py changed, reloading.
INFO:django.utils.autoreload:D:\django projects\exel_data\project\update_emails_from_excel_file.py changed, reloading.
INFO:django.utils.autoreload:D:\django projects\exel_data\project\update_emails_from_excel_file.py changed, reloading.
INFO:django.utils.autoreload:D:\django projects\exel_data\project\models.py changed, reloading.
INFO:django.utils.autoreload:D:\django projects\exel_data\project\models.py changed, reloading.
INFO:django.utils.autoreload:D:\django projects\exel_data\project\models.py changed, reloading.
INFO:django.utils.autoreload:D:\django projects\exel_data\project\models.py changed, reloading.
INFO:django.utils.autoreload:D:\django projects\exel_data\project\store_data.py changed, reloading.
INFO:django.utils.autoreload:D:\django projects\exel_data\exel_data\urls.py changed, reloading.
INFO:django.utils.autoreload:D:\django projects\exel_data\project\views.py changed, reloading.
ERROR:django.request:Internal Server Error: /upload_excel
Traceback (most recent call last):
  File "D:\django projects\exel_data\venv\lib\site-packages\django\core\handlers\exception.py", line 47, in inner
    response = get_response(request)
  File "D:\django projects\exel_data\venv\lib\site-packages\django\core\handlers\base.py", line 181, in _get_response
    response = wrapped_callback(request, *callback_args, **callback_kwargs)
  File "D:\django projects\exel_data\project\views.py", line 30, in Import_excel_file
    save_obj(row)
  File "D:\django projects\exel_data\project\store_data.py", line 8, in save_obj
    , country=row.country, city=row.city)
  File "D:\django projects\exel_data\venv\lib\site-packages\pandas\core\generic.py", line 5487, in __getattr__
    return object.__getattribute__(self, name)
AttributeError: 'Series' object has no attribute 'country'
INFO:django.utils.autoreload:D:\django projects\exel_data\project\store_data.py changed, reloading.
ERROR:django.request:Internal Server Error: /upload_excel
Traceback (most recent call last):
  File "D:\django projects\exel_data\venv\lib\site-packages\django\core\handlers\exception.py", line 47, in inner
    response = get_response(request)
  File "D:\django projects\exel_data\venv\lib\site-packages\django\core\handlers\base.py", line 181, in _get_response
    response = wrapped_callback(request, *callback_args, **callback_kwargs)
  File "D:\django projects\exel_data\project\views.py", line 30, in Import_excel_file
    save_obj(row)
  File "D:\django projects\exel_data\project\store_data.py", line 8, in save_obj
    , country=row.country, city=row.city)
  File "D:\django projects\exel_data\venv\lib\site-packages\pandas\core\generic.py", line 5487, in __getattr__
    return object.__getattribute__(self, name)
AttributeError: 'Series' object has no attribute 'country'
ERROR:django.request:Internal Server Error: /upload_excel
Traceback (most recent call last):
  File "D:\django projects\exel_data\venv\lib\site-packages\django\db\backends\utils.py", line 84, in _execute
    return self.cursor.execute(sql, params)
  File "D:\django projects\exel_data\venv\lib\site-packages\django\db\backends\mysql\base.py", line 73, in execute
    return self.cursor.execute(query, args)
  File "D:\django projects\exel_data\venv\lib\site-packages\MySQLdb\cursors.py", line 206, in execute
    res = self._query(query)
  File "D:\django projects\exel_data\venv\lib\site-packages\MySQLdb\cursors.py", line 319, in _query
    db.query(q)
  File "D:\django projects\exel_data\venv\lib\site-packages\MySQLdb\connections.py", line 254, in query
    _mysql.connection.query(self, query)
MySQLdb._exceptions.DataError: (1406, "Data too long for column 'title' at row 1")

The above exception was the direct cause of the following exception:

Traceback (most recent call last):
  File "D:\django projects\exel_data\venv\lib\site-packages\django\core\handlers\exception.py", line 47, in inner
    response = get_response(request)
  File "D:\django projects\exel_data\venv\lib\site-packages\django\core\handlers\base.py", line 181, in _get_response
    response = wrapped_callback(request, *callback_args, **callback_kwargs)
  File "D:\django projects\exel_data\project\views.py", line 30, in Import_excel_file
    save_obj(row)
  File "D:\django projects\exel_data\project\store_data.py", line 7, in save_obj
    Person.objects.create(first_name=row.first_name, last_name=row.last_name, email=row.email, created_at=now, title=row
  File "D:\django projects\exel_data\venv\lib\site-packages\django\db\models\manager.py", line 85, in manager_method
    return getattr(self.get_queryset(), name)(*args, **kwargs)
  File "D:\django projects\exel_data\venv\lib\site-packages\django\db\models\query.py", line 453, in create
    obj.save(force_insert=True, using=self.db)
  File "D:\django projects\exel_data\venv\lib\site-packages\django\db\models\base.py", line 726, in save
    self.save_base(using=using, force_insert=force_insert,
  File "D:\django projects\exel_data\venv\lib\site-packages\django\db\models\base.py", line 763, in save_base
    updated = self._save_table(
  File "D:\django projects\exel_data\venv\lib\site-packages\django\db\models\base.py", line 868, in _save_table
    results = self._do_insert(cls._base_manager, using, fields, returning_fields, raw)
  File "D:\django projects\exel_data\venv\lib\site-packages\django\db\models\base.py", line 906, in _do_insert
    return manager._insert(
  File "D:\django projects\exel_data\venv\lib\site-packages\django\db\models\manager.py", line 85, in manager_method
    return getattr(self.get_queryset(), name)(*args, **kwargs)
  File "D:\django projects\exel_data\venv\lib\site-packages\django\db\models\query.py", line 1270, in _insert
    return query.get_compiler(using=using).execute_sql(returning_fields)
  File "D:\django projects\exel_data\venv\lib\site-packages\django\db\models\sql\compiler.py", line 1416, in execute_sql
    cursor.execute(sql, params)
  File "D:\django projects\exel_data\venv\lib\site-packages\django\db\backends\utils.py", line 98, in execute
    return super().execute(sql, params)
  File "D:\django projects\exel_data\venv\lib\site-packages\django\db\backends\utils.py", line 66, in execute
    return self._execute_with_wrappers(sql, params, many=False, executor=self._execute)
  File "D:\django projects\exel_data\venv\lib\site-packages\django\db\backends\utils.py", line 75, in _execute_with_wrappers
    return executor(sql, params, many, context)
  File "D:\django projects\exel_data\venv\lib\site-packages\django\db\backends\utils.py", line 84, in _execute
    return self.cursor.execute(sql, params)
  File "D:\django projects\exel_data\venv\lib\site-packages\django\db\utils.py", line 90, in __exit__
    raise dj_exc_value.with_traceback(traceback) from exc_value
  File "D:\django projects\exel_data\venv\lib\site-packages\django\db\backends\utils.py", line 84, in _execute
    return self.cursor.execute(sql, params)
  File "D:\django projects\exel_data\venv\lib\site-packages\django\db\backends\mysql\base.py", line 73, in execute
    return self.cursor.execute(query, args)
  File "D:\django projects\exel_data\venv\lib\site-packages\MySQLdb\cursors.py", line 206, in execute
    res = self._query(query)
  File "D:\django projects\exel_data\venv\lib\site-packages\MySQLdb\cursors.py", line 319, in _query
    db.query(q)
  File "D:\django projects\exel_data\venv\lib\site-packages\MySQLdb\connections.py", line 254, in query
    _mysql.connection.query(self, query)
django.db.utils.DataError: (1406, "Data too long for column 'title' at row 1")
ERROR:django.request:Internal Server Error: /upload_excel
Traceback (most recent call last):
  File "D:\django projects\exel_data\venv\lib\site-packages\django\db\backends\utils.py", line 84, in _execute
    return self.cursor.execute(sql, params)
  File "D:\django projects\exel_data\venv\lib\site-packages\django\db\backends\mysql\base.py", line 73, in execute
    return self.cursor.execute(query, args)
  File "D:\django projects\exel_data\venv\lib\site-packages\MySQLdb\cursors.py", line 206, in execute
    res = self._query(query)
  File "D:\django projects\exel_data\venv\lib\site-packages\MySQLdb\cursors.py", line 319, in _query
    db.query(q)
  File "D:\django projects\exel_data\venv\lib\site-packages\MySQLdb\connections.py", line 254, in query
    _mysql.connection.query(self, query)
MySQLdb._exceptions.DataError: (1406, "Data too long for column 'title' at row 1")

The above exception was the direct cause of the following exception:

Traceback (most recent call last):
  File "D:\django projects\exel_data\venv\lib\site-packages\django\core\handlers\exception.py", line 47, in inner
    response = get_response(request)
  File "D:\django projects\exel_data\venv\lib\site-packages\django\core\handlers\base.py", line 181, in _get_response
    response = wrapped_callback(request, *callback_args, **callback_kwargs)
  File "D:\django projects\exel_data\project\views.py", line 30, in Import_excel_file
    save_obj(row)
  File "D:\django projects\exel_data\project\store_data.py", line 7, in save_obj
    Person.objects.create(first_name=row.first_name, last_name=row.last_name, email=row.email, created_at=now, title=row
  File "D:\django projects\exel_data\venv\lib\site-packages\django\db\models\manager.py", line 85, in manager_method
    return getattr(self.get_queryset(), name)(*args, **kwargs)
  File "D:\django projects\exel_data\venv\lib\site-packages\django\db\models\query.py", line 453, in create
    obj.save(force_insert=True, using=self.db)
  File "D:\django projects\exel_data\venv\lib\site-packages\django\db\models\base.py", line 726, in save
    self.save_base(using=using, force_insert=force_insert,
  File "D:\django projects\exel_data\venv\lib\site-packages\django\db\models\base.py", line 763, in save_base
    updated = self._save_table(
  File "D:\django projects\exel_data\venv\lib\site-packages\django\db\models\base.py", line 868, in _save_table
    results = self._do_insert(cls._base_manager, using, fields, returning_fields, raw)
  File "D:\django projects\exel_data\venv\lib\site-packages\django\db\models\base.py", line 906, in _do_insert
    return manager._insert(
  File "D:\django projects\exel_data\venv\lib\site-packages\django\db\models\manager.py", line 85, in manager_method
    return getattr(self.get_queryset(), name)(*args, **kwargs)
  File "D:\django projects\exel_data\venv\lib\site-packages\django\db\models\query.py", line 1270, in _insert
    return query.get_compiler(using=using).execute_sql(returning_fields)
  File "D:\django projects\exel_data\venv\lib\site-packages\django\db\models\sql\compiler.py", line 1416, in execute_sql
    cursor.execute(sql, params)
  File "D:\django projects\exel_data\venv\lib\site-packages\django\db\backends\utils.py", line 98, in execute
    return super().execute(sql, params)
  File "D:\django projects\exel_data\venv\lib\site-packages\django\db\backends\utils.py", line 66, in execute
    return self._execute_with_wrappers(sql, params, many=False, executor=self._execute)
  File "D:\django projects\exel_data\venv\lib\site-packages\django\db\backends\utils.py", line 75, in _execute_with_wrappers
    return executor(sql, params, many, context)
  File "D:\django projects\exel_data\venv\lib\site-packages\django\db\backends\utils.py", line 84, in _execute
    return self.cursor.execute(sql, params)
  File "D:\django projects\exel_data\venv\lib\site-packages\django\db\utils.py", line 90, in __exit__
    raise dj_exc_value.with_traceback(traceback) from exc_value
  File "D:\django projects\exel_data\venv\lib\site-packages\django\db\backends\utils.py", line 84, in _execute
    return self.cursor.execute(sql, params)
  File "D:\django projects\exel_data\venv\lib\site-packages\django\db\backends\mysql\base.py", line 73, in execute
    return self.cursor.execute(query, args)
  File "D:\django projects\exel_data\venv\lib\site-packages\MySQLdb\cursors.py", line 206, in execute
    res = self._query(query)
  File "D:\django projects\exel_data\venv\lib\site-packages\MySQLdb\cursors.py", line 319, in _query
    db.query(q)
  File "D:\django projects\exel_data\venv\lib\site-packages\MySQLdb\connections.py", line 254, in query
    _mysql.connection.query(self, query)
django.db.utils.DataError: (1406, "Data too long for column 'title' at row 1")
INFO:django.utils.autoreload:D:\django projects\exel_data\project\models.py changed, reloading.
ERROR:django.request:Internal Server Error: /upload_excel
Traceback (most recent call last):
  File "D:\django projects\exel_data\venv\lib\site-packages\django\db\backends\utils.py", line 84, in _execute
    return self.cursor.execute(sql, params)
  File "D:\django projects\exel_data\venv\lib\site-packages\django\db\backends\mysql\base.py", line 73, in execute
    return self.cursor.execute(query, args)
  File "D:\django projects\exel_data\venv\lib\site-packages\MySQLdb\cursors.py", line 206, in execute
    res = self._query(query)
  File "D:\django projects\exel_data\venv\lib\site-packages\MySQLdb\cursors.py", line 319, in _query
    db.query(q)
  File "D:\django projects\exel_data\venv\lib\site-packages\MySQLdb\connections.py", line 254, in query
    _mysql.connection.query(self, query)
MySQLdb._exceptions.DataError: (1406, "Data too long for column 'title' at row 1")

The above exception was the direct cause of the following exception:

Traceback (most recent call last):
  File "D:\django projects\exel_data\venv\lib\site-packages\django\core\handlers\exception.py", line 47, in inner
    response = get_response(request)
  File "D:\django projects\exel_data\venv\lib\site-packages\django\core\handlers\base.py", line 181, in _get_response
    response = wrapped_callback(request, *callback_args, **callback_kwargs)
  File "D:\django projects\exel_data\project\views.py", line 30, in Import_excel_file
    save_obj(row)
  File "D:\django projects\exel_data\project\store_data.py", line 7, in save_obj
    Person.objects.create(first_name=row.first_name, last_name=row.last_name, email=row.email, created_at=now, title=row
  File "D:\django projects\exel_data\venv\lib\site-packages\django\db\models\manager.py", line 85, in manager_method
    return getattr(self.get_queryset(), name)(*args, **kwargs)
  File "D:\django projects\exel_data\venv\lib\site-packages\django\db\models\query.py", line 453, in create
    obj.save(force_insert=True, using=self.db)
  File "D:\django projects\exel_data\venv\lib\site-packages\django\db\models\base.py", line 726, in save
    self.save_base(using=using, force_insert=force_insert,
  File "D:\django projects\exel_data\venv\lib\site-packages\django\db\models\base.py", line 763, in save_base
    updated = self._save_table(
  File "D:\django projects\exel_data\venv\lib\site-packages\django\db\models\base.py", line 868, in _save_table
    results = self._do_insert(cls._base_manager, using, fields, returning_fields, raw)
  File "D:\django projects\exel_data\venv\lib\site-packages\django\db\models\base.py", line 906, in _do_insert
    return manager._insert(
  File "D:\django projects\exel_data\venv\lib\site-packages\django\db\models\manager.py", line 85, in manager_method
    return getattr(self.get_queryset(), name)(*args, **kwargs)
  File "D:\django projects\exel_data\venv\lib\site-packages\django\db\models\query.py", line 1270, in _insert
    return query.get_compiler(using=using).execute_sql(returning_fields)
  File "D:\django projects\exel_data\venv\lib\site-packages\django\db\models\sql\compiler.py", line 1416, in execute_sql
    cursor.execute(sql, params)
  File "D:\django projects\exel_data\venv\lib\site-packages\django\db\backends\utils.py", line 98, in execute
    return super().execute(sql, params)
  File "D:\django projects\exel_data\venv\lib\site-packages\django\db\backends\utils.py", line 66, in execute
    return self._execute_with_wrappers(sql, params, many=False, executor=self._execute)
  File "D:\django projects\exel_data\venv\lib\site-packages\django\db\backends\utils.py", line 75, in _execute_with_wrappers
    return executor(sql, params, many, context)
  File "D:\django projects\exel_data\venv\lib\site-packages\django\db\backends\utils.py", line 84, in _execute
    return self.cursor.execute(sql, params)
  File "D:\django projects\exel_data\venv\lib\site-packages\django\db\utils.py", line 90, in __exit__
    raise dj_exc_value.with_traceback(traceback) from exc_value
  File "D:\django projects\exel_data\venv\lib\site-packages\django\db\backends\utils.py", line 84, in _execute
    return self.cursor.execute(sql, params)
  File "D:\django projects\exel_data\venv\lib\site-packages\django\db\backends\mysql\base.py", line 73, in execute
    return self.cursor.execute(query, args)
  File "D:\django projects\exel_data\venv\lib\site-packages\MySQLdb\cursors.py", line 206, in execute
    res = self._query(query)
  File "D:\django projects\exel_data\venv\lib\site-packages\MySQLdb\cursors.py", line 319, in _query
    db.query(q)
  File "D:\django projects\exel_data\venv\lib\site-packages\MySQLdb\connections.py", line 254, in query
    _mysql.connection.query(self, query)
django.db.utils.DataError: (1406, "Data too long for column 'title' at row 1")
ERROR:django.request:Internal Server Error: /upload_excel
Traceback (most recent call last):
  File "D:\django projects\exel_data\venv\lib\site-packages\django\db\backends\utils.py", line 84, in _execute
    return self.cursor.execute(sql, params)
  File "D:\django projects\exel_data\venv\lib\site-packages\django\db\backends\mysql\base.py", line 73, in execute
    return self.cursor.execute(query, args)
  File "D:\django projects\exel_data\venv\lib\site-packages\MySQLdb\cursors.py", line 206, in execute
    res = self._query(query)
  File "D:\django projects\exel_data\venv\lib\site-packages\MySQLdb\cursors.py", line 319, in _query
    db.query(q)
  File "D:\django projects\exel_data\venv\lib\site-packages\MySQLdb\connections.py", line 254, in query
    _mysql.connection.query(self, query)
MySQLdb._exceptions.DataError: (1406, "Data too long for column 'title' at row 1")

The above exception was the direct cause of the following exception:

Traceback (most recent call last):
  File "D:\django projects\exel_data\venv\lib\site-packages\django\core\handlers\exception.py", line 47, in inner
    response = get_response(request)
  File "D:\django projects\exel_data\venv\lib\site-packages\django\core\handlers\base.py", line 181, in _get_response
    response = wrapped_callback(request, *callback_args, **callback_kwargs)
  File "D:\django projects\exel_data\project\views.py", line 30, in Import_excel_file
    save_obj(row)
  File "D:\django projects\exel_data\project\store_data.py", line 7, in save_obj
    Person.objects.create(first_name=row.first_name, last_name=row.last_name, email=row.email, created_at=now, title=row
  File "D:\django projects\exel_data\venv\lib\site-packages\django\db\models\manager.py", line 85, in manager_method
    return getattr(self.get_queryset(), name)(*args, **kwargs)
  File "D:\django projects\exel_data\venv\lib\site-packages\django\db\models\query.py", line 453, in create
    obj.save(force_insert=True, using=self.db)
  File "D:\django projects\exel_data\venv\lib\site-packages\django\db\models\base.py", line 726, in save
    self.save_base(using=using, force_insert=force_insert,
  File "D:\django projects\exel_data\venv\lib\site-packages\django\db\models\base.py", line 763, in save_base
    updated = self._save_table(
  File "D:\django projects\exel_data\venv\lib\site-packages\django\db\models\base.py", line 868, in _save_table
    results = self._do_insert(cls._base_manager, using, fields, returning_fields, raw)
  File "D:\django projects\exel_data\venv\lib\site-packages\django\db\models\base.py", line 906, in _do_insert
    return manager._insert(
  File "D:\django projects\exel_data\venv\lib\site-packages\django\db\models\manager.py", line 85, in manager_method
    return getattr(self.get_queryset(), name)(*args, **kwargs)
  File "D:\django projects\exel_data\venv\lib\site-packages\django\db\models\query.py", line 1270, in _insert
    return query.get_compiler(using=using).execute_sql(returning_fields)
  File "D:\django projects\exel_data\venv\lib\site-packages\django\db\models\sql\compiler.py", line 1416, in execute_sql
    cursor.execute(sql, params)
  File "D:\django projects\exel_data\venv\lib\site-packages\django\db\backends\utils.py", line 98, in execute
    return super().execute(sql, params)
  File "D:\django projects\exel_data\venv\lib\site-packages\django\db\backends\utils.py", line 66, in execute
    return self._execute_with_wrappers(sql, params, many=False, executor=self._execute)
  File "D:\django projects\exel_data\venv\lib\site-packages\django\db\backends\utils.py", line 75, in _execute_with_wrappers
    return executor(sql, params, many, context)
  File "D:\django projects\exel_data\venv\lib\site-packages\django\db\backends\utils.py", line 84, in _execute
    return self.cursor.execute(sql, params)
  File "D:\django projects\exel_data\venv\lib\site-packages\django\db\utils.py", line 90, in __exit__
    raise dj_exc_value.with_traceback(traceback) from exc_value
  File "D:\django projects\exel_data\venv\lib\site-packages\django\db\backends\utils.py", line 84, in _execute
    return self.cursor.execute(sql, params)
  File "D:\django projects\exel_data\venv\lib\site-packages\django\db\backends\mysql\base.py", line 73, in execute
    return self.cursor.execute(query, args)
  File "D:\django projects\exel_data\venv\lib\site-packages\MySQLdb\cursors.py", line 206, in execute
    res = self._query(query)
  File "D:\django projects\exel_data\venv\lib\site-packages\MySQLdb\cursors.py", line 319, in _query
    db.query(q)
  File "D:\django projects\exel_data\venv\lib\site-packages\MySQLdb\connections.py", line 254, in query
    _mysql.connection.query(self, query)
django.db.utils.DataError: (1406, "Data too long for column 'title' at row 1")
INFO:django.utils.autoreload:D:\django projects\exel_data\project\models.py changed, reloading.
ERROR:django.request:Internal Server Error: /upload_excel
Traceback (most recent call last):
  File "D:\django projects\exel_data\venv\lib\site-packages\django\db\backends\utils.py", line 84, in _execute
    return self.cursor.execute(sql, params)
  File "D:\django projects\exel_data\venv\lib\site-packages\django\db\backends\mysql\base.py", line 73, in execute
    return self.cursor.execute(query, args)
  File "D:\django projects\exel_data\venv\lib\site-packages\MySQLdb\cursors.py", line 206, in execute
    res = self._query(query)
  File "D:\django projects\exel_data\venv\lib\site-packages\MySQLdb\cursors.py", line 319, in _query
    db.query(q)
  File "D:\django projects\exel_data\venv\lib\site-packages\MySQLdb\connections.py", line 254, in query
    _mysql.connection.query(self, query)
MySQLdb._exceptions.DataError: (1406, "Data too long for column 'title' at row 1")

The above exception was the direct cause of the following exception:

Traceback (most recent call last):
  File "D:\django projects\exel_data\venv\lib\site-packages\django\core\handlers\exception.py", line 47, in inner
    response = get_response(request)
  File "D:\django projects\exel_data\venv\lib\site-packages\django\core\handlers\base.py", line 181, in _get_response
    response = wrapped_callback(request, *callback_args, **callback_kwargs)
  File "D:\django projects\exel_data\project\views.py", line 30, in Import_excel_file
    save_obj(row)
  File "D:\django projects\exel_data\project\store_data.py", line 7, in save_obj
    Person.objects.create(first_name=row.first_name, last_name=row.last_name, email=row.email, created_at=now, title=row
  File "D:\django projects\exel_data\venv\lib\site-packages\django\db\models\manager.py", line 85, in manager_method
    return getattr(self.get_queryset(), name)(*args, **kwargs)
  File "D:\django projects\exel_data\venv\lib\site-packages\django\db\models\query.py", line 453, in create
    obj.save(force_insert=True, using=self.db)
  File "D:\django projects\exel_data\venv\lib\site-packages\django\db\models\base.py", line 726, in save
    self.save_base(using=using, force_insert=force_insert,
  File "D:\django projects\exel_data\venv\lib\site-packages\django\db\models\base.py", line 763, in save_base
    updated = self._save_table(
  File "D:\django projects\exel_data\venv\lib\site-packages\django\db\models\base.py", line 868, in _save_table
    results = self._do_insert(cls._base_manager, using, fields, returning_fields, raw)
  File "D:\django projects\exel_data\venv\lib\site-packages\django\db\models\base.py", line 906, in _do_insert
    return manager._insert(
  File "D:\django projects\exel_data\venv\lib\site-packages\django\db\models\manager.py", line 85, in manager_method
    return getattr(self.get_queryset(), name)(*args, **kwargs)
  File "D:\django projects\exel_data\venv\lib\site-packages\django\db\models\query.py", line 1270, in _insert
    return query.get_compiler(using=using).execute_sql(returning_fields)
  File "D:\django projects\exel_data\venv\lib\site-packages\django\db\models\sql\compiler.py", line 1416, in execute_sql
    cursor.execute(sql, params)
  File "D:\django projects\exel_data\venv\lib\site-packages\django\db\backends\utils.py", line 98, in execute
    return super().execute(sql, params)
  File "D:\django projects\exel_data\venv\lib\site-packages\django\db\backends\utils.py", line 66, in execute
    return self._execute_with_wrappers(sql, params, many=False, executor=self._execute)
  File "D:\django projects\exel_data\venv\lib\site-packages\django\db\backends\utils.py", line 75, in _execute_with_wrappers
    return executor(sql, params, many, context)
  File "D:\django projects\exel_data\venv\lib\site-packages\django\db\backends\utils.py", line 84, in _execute
    return self.cursor.execute(sql, params)
  File "D:\django projects\exel_data\venv\lib\site-packages\django\db\utils.py", line 90, in __exit__
    raise dj_exc_value.with_traceback(traceback) from exc_value
  File "D:\django projects\exel_data\venv\lib\site-packages\django\db\backends\utils.py", line 84, in _execute
    return self.cursor.execute(sql, params)
  File "D:\django projects\exel_data\venv\lib\site-packages\django\db\backends\mysql\base.py", line 73, in execute
    return self.cursor.execute(query, args)
  File "D:\django projects\exel_data\venv\lib\site-packages\MySQLdb\cursors.py", line 206, in execute
    res = self._query(query)
  File "D:\django projects\exel_data\venv\lib\site-packages\MySQLdb\cursors.py", line 319, in _query
    db.query(q)
  File "D:\django projects\exel_data\venv\lib\site-packages\MySQLdb\connections.py", line 254, in query
    _mysql.connection.query(self, query)
django.db.utils.DataError: (1406, "Data too long for column 'title' at row 1")
INFO:django.utils.autoreload:D:\django projects\exel_data\project\models.py changed, reloading.
ERROR:django.request:Internal Server Error: /upload_excel
Traceback (most recent call last):
  File "D:\django projects\exel_data\venv\lib\site-packages\django\core\handlers\exception.py", line 47, in inner
    response = get_response(request)
  File "D:\django projects\exel_data\venv\lib\site-packages\django\core\handlers\base.py", line 181, in _get_response
    response = wrapped_callback(request, *callback_args, **callback_kwargs)
  File "D:\django projects\exel_data\project\views.py", line 30, in Import_excel_file
    save_obj(row)
  File "D:\django projects\exel_data\project\store_data.py", line 7, in save_obj
    Person.objects.create(first_name=row.first_name, last_name=row.last_name, email=row.email, created_at=now, title=row
  File "D:\django projects\exel_data\venv\lib\site-packages\django\db\models\manager.py", line 85, in manager_method
    return getattr(self.get_queryset(), name)(*args, **kwargs)
  File "D:\django projects\exel_data\venv\lib\site-packages\django\db\models\query.py", line 451, in create
    obj = self.model(**kwargs)
  File "D:\django projects\exel_data\venv\lib\site-packages\django\db\models\base.py", line 503, in __init__
    raise TypeError("%s() got an unexpected keyword argument '%s'" % (cls.__name__, kwarg))
TypeError: Person() got an unexpected keyword argument 'title'
INFO:django.utils.autoreload:D:\django projects\exel_data\project\models.py changed, reloading.
ERROR:django.request:Internal Server Error: /upload_excel
Traceback (most recent call last):
  File "D:\django projects\exel_data\venv\lib\site-packages\django\db\backends\utils.py", line 84, in _execute
    return self.cursor.execute(sql, params)
  File "D:\django projects\exel_data\venv\lib\site-packages\django\db\backends\mysql\base.py", line 73, in execute
    return self.cursor.execute(query, args)
  File "D:\django projects\exel_data\venv\lib\site-packages\MySQLdb\cursors.py", line 206, in execute
    res = self._query(query)
  File "D:\django projects\exel_data\venv\lib\site-packages\MySQLdb\cursors.py", line 319, in _query
    db.query(q)
  File "D:\django projects\exel_data\venv\lib\site-packages\MySQLdb\connections.py", line 254, in query
    _mysql.connection.query(self, query)
MySQLdb._exceptions.DataError: (1406, "Data too long for column 'title' at row 1")

The above exception was the direct cause of the following exception:

Traceback (most recent call last):
  File "D:\django projects\exel_data\venv\lib\site-packages\django\core\handlers\exception.py", line 47, in inner
    response = get_response(request)
  File "D:\django projects\exel_data\venv\lib\site-packages\django\core\handlers\base.py", line 181, in _get_response
    response = wrapped_callback(request, *callback_args, **callback_kwargs)
  File "D:\django projects\exel_data\project\views.py", line 30, in Import_excel_file
    save_obj(row)
  File "D:\django projects\exel_data\project\store_data.py", line 7, in save_obj
    Person.objects.create(first_name=row.first_name, last_name=row.last_name, email=row.email, created_at=now, title=row
  File "D:\django projects\exel_data\venv\lib\site-packages\django\db\models\manager.py", line 85, in manager_method
    return getattr(self.get_queryset(), name)(*args, **kwargs)
  File "D:\django projects\exel_data\venv\lib\site-packages\django\db\models\query.py", line 453, in create
    obj.save(force_insert=True, using=self.db)
  File "D:\django projects\exel_data\venv\lib\site-packages\django\db\models\base.py", line 726, in save
    self.save_base(using=using, force_insert=force_insert,
  File "D:\django projects\exel_data\venv\lib\site-packages\django\db\models\base.py", line 763, in save_base
    updated = self._save_table(
  File "D:\django projects\exel_data\venv\lib\site-packages\django\db\models\base.py", line 868, in _save_table
    results = self._do_insert(cls._base_manager, using, fields, returning_fields, raw)
  File "D:\django projects\exel_data\venv\lib\site-packages\django\db\models\base.py", line 906, in _do_insert
    return manager._insert(
  File "D:\django projects\exel_data\venv\lib\site-packages\django\db\models\manager.py", line 85, in manager_method
    return getattr(self.get_queryset(), name)(*args, **kwargs)
  File "D:\django projects\exel_data\venv\lib\site-packages\django\db\models\query.py", line 1270, in _insert
    return query.get_compiler(using=using).execute_sql(returning_fields)
  File "D:\django projects\exel_data\venv\lib\site-packages\django\db\models\sql\compiler.py", line 1416, in execute_sql
    cursor.execute(sql, params)
  File "D:\django projects\exel_data\venv\lib\site-packages\django\db\backends\utils.py", line 98, in execute
    return super().execute(sql, params)
  File "D:\django projects\exel_data\venv\lib\site-packages\django\db\backends\utils.py", line 66, in execute
    return self._execute_with_wrappers(sql, params, many=False, executor=self._execute)
  File "D:\django projects\exel_data\venv\lib\site-packages\django\db\backends\utils.py", line 75, in _execute_with_wrappers
    return executor(sql, params, many, context)
  File "D:\django projects\exel_data\venv\lib\site-packages\django\db\backends\utils.py", line 84, in _execute
    return self.cursor.execute(sql, params)
  File "D:\django projects\exel_data\venv\lib\site-packages\django\db\utils.py", line 90, in __exit__
    raise dj_exc_value.with_traceback(traceback) from exc_value
  File "D:\django projects\exel_data\venv\lib\site-packages\django\db\backends\utils.py", line 84, in _execute
    return self.cursor.execute(sql, params)
  File "D:\django projects\exel_data\venv\lib\site-packages\django\db\backends\mysql\base.py", line 73, in execute
    return self.cursor.execute(query, args)
  File "D:\django projects\exel_data\venv\lib\site-packages\MySQLdb\cursors.py", line 206, in execute
    res = self._query(query)
  File "D:\django projects\exel_data\venv\lib\site-packages\MySQLdb\cursors.py", line 319, in _query
    db.query(q)
  File "D:\django projects\exel_data\venv\lib\site-packages\MySQLdb\connections.py", line 254, in query
    _mysql.connection.query(self, query)
django.db.utils.DataError: (1406, "Data too long for column 'title' at row 1")
INFO:django.utils.autoreload:D:\django projects\exel_data\project\models.py changed, reloading.
ERROR:django.request:Internal Server Error: /upload_excel
Traceback (most recent call last):
  File "D:\django projects\exel_data\venv\lib\site-packages\django\core\handlers\exception.py", line 47, in inner
    response = get_response(request)
  File "D:\django projects\exel_data\venv\lib\site-packages\django\core\handlers\base.py", line 181, in _get_response
    response = wrapped_callback(request, *callback_args, **callback_kwargs)
  File "D:\django projects\exel_data\project\views.py", line 30, in Import_excel_file
    save_obj(row)
  File "D:\django projects\exel_data\project\store_data.py", line 7, in save_obj
    Person.objects.create(first_name=row.first_name, last_name=row.last_name, email=row.email, created_at=now, title=row
  File "D:\django projects\exel_data\venv\lib\site-packages\django\db\models\manager.py", line 85, in manager_method
    return getattr(self.get_queryset(), name)(*args, **kwargs)
  File "D:\django projects\exel_data\venv\lib\site-packages\django\db\models\query.py", line 451, in create
    obj = self.model(**kwargs)
  File "D:\django projects\exel_data\venv\lib\site-packages\django\db\models\base.py", line 503, in __init__
    raise TypeError("%s() got an unexpected keyword argument '%s'" % (cls.__name__, kwarg))
TypeError: Person() got an unexpected keyword argument 'title'
ERROR:django.request:Internal Server Error: /upload_excel
Traceback (most recent call last):
  File "D:\django projects\exel_data\venv\lib\site-packages\django\core\handlers\exception.py", line 47, in inner
    response = get_response(request)
  File "D:\django projects\exel_data\venv\lib\site-packages\django\core\handlers\base.py", line 181, in _get_response
    response = wrapped_callback(request, *callback_args, **callback_kwargs)
  File "D:\django projects\exel_data\project\views.py", line 30, in Import_excel_file
    save_obj(row)
  File "D:\django projects\exel_data\project\store_data.py", line 7, in save_obj
    Person.objects.create(first_name=row.first_name, last_name=row.last_name, email=row.email, created_at=now, title=row
  File "D:\django projects\exel_data\venv\lib\site-packages\django\db\models\manager.py", line 85, in manager_method
    return getattr(self.get_queryset(), name)(*args, **kwargs)
  File "D:\django projects\exel_data\venv\lib\site-packages\django\db\models\query.py", line 451, in create
    obj = self.model(**kwargs)
  File "D:\django projects\exel_data\venv\lib\site-packages\django\db\models\base.py", line 503, in __init__
    raise TypeError("%s() got an unexpected keyword argument '%s'" % (cls.__name__, kwarg))
TypeError: Person() got an unexpected keyword argument 'title'
INFO:django.utils.autoreload:D:\django projects\exel_data\project\store_data.py changed, reloading.
DEBUG:root:('Valid Row : 3', 'Invalid Row: 0')
WARNING:django.request:Not Found: /update_email
ERROR:django.request:Internal Server Error: /update_excel
Traceback (most recent call last):
  File "D:\django projects\exel_data\venv\lib\site-packages\django\core\handlers\exception.py", line 47, in inner
    response = get_response(request)
  File "D:\django projects\exel_data\venv\lib\site-packages\django\core\handlers\base.py", line 181, in _get_response
    response = wrapped_callback(request, *callback_args, **callback_kwargs)
  File "D:\django projects\exel_data\project\update_row_from_excel_file.py", line 31, in update_email_excel_file
    get_row.title = row.title
  File "D:\django projects\exel_data\venv\lib\site-packages\pandas\core\generic.py", line 5487, in __getattr__
    return object.__getattribute__(self, name)
AttributeError: 'Series' object has no attribute 'title'
INFO:django.utils.autoreload:D:\django projects\exel_data\project\update_row_from_excel_file.py changed, reloading.
DEBUG:root:('Updates Row : 3', 'Invalid Row: 0')
WARNING:django.request:Not Found: /favicon.ico
WARNING:django.security.csrf:Forbidden (CSRF token missing or incorrect.): /upload_excel
ERROR:django.request:Internal Server Error: /upload_excel
Traceback (most recent call last):
  File "D:\django projects\exel_data\venv\lib\site-packages\django\db\backends\utils.py", line 84, in _execute
    return self.cursor.execute(sql, params)
  File "D:\django projects\exel_data\venv\lib\site-packages\django\db\backends\mysql\base.py", line 73, in execute
    return self.cursor.execute(query, args)
  File "D:\django projects\exel_data\venv\lib\site-packages\MySQLdb\cursors.py", line 206, in execute
    res = self._query(query)
  File "D:\django projects\exel_data\venv\lib\site-packages\MySQLdb\cursors.py", line 319, in _query
    db.query(q)
  File "D:\django projects\exel_data\venv\lib\site-packages\MySQLdb\connections.py", line 254, in query
    _mysql.connection.query(self, query)
MySQLdb._exceptions.IntegrityError: (1062, "Duplicate entry 'ali@gmail.com' for key 'project_person.project_person_email_82bd4bf0_uniq'")

The above exception was the direct cause of the following exception:

Traceback (most recent call last):
  File "D:\django projects\exel_data\venv\lib\site-packages\django\core\handlers\exception.py", line 47, in inner
    response = get_response(request)
  File "D:\django projects\exel_data\venv\lib\site-packages\django\core\handlers\base.py", line 181, in _get_response
    response = wrapped_callback(request, *callback_args, **callback_kwargs)
  File "D:\django projects\exel_data\project\views.py", line 29, in Import_excel_file
    save_obj(row)
  File "D:\django projects\exel_data\project\store_data.py", line 7, in save_obj
    Person.objects.create(first_name=row.first_name, last_name=row.last_name, email=row.email, created_at=now
  File "D:\django projects\exel_data\venv\lib\site-packages\django\db\models\manager.py", line 85, in manager_method
    return getattr(self.get_queryset(), name)(*args, **kwargs)
  File "D:\django projects\exel_data\venv\lib\site-packages\django\db\models\query.py", line 453, in create
    obj.save(force_insert=True, using=self.db)
  File "D:\django projects\exel_data\venv\lib\site-packages\django\db\models\base.py", line 726, in save
    self.save_base(using=using, force_insert=force_insert,
  File "D:\django projects\exel_data\venv\lib\site-packages\django\db\models\base.py", line 763, in save_base
    updated = self._save_table(
  File "D:\django projects\exel_data\venv\lib\site-packages\django\db\models\base.py", line 868, in _save_table
    results = self._do_insert(cls._base_manager, using, fields, returning_fields, raw)
  File "D:\django projects\exel_data\venv\lib\site-packages\django\db\models\base.py", line 906, in _do_insert
    return manager._insert(
  File "D:\django projects\exel_data\venv\lib\site-packages\django\db\models\manager.py", line 85, in manager_method
    return getattr(self.get_queryset(), name)(*args, **kwargs)
  File "D:\django projects\exel_data\venv\lib\site-packages\django\db\models\query.py", line 1270, in _insert
    return query.get_compiler(using=using).execute_sql(returning_fields)
  File "D:\django projects\exel_data\venv\lib\site-packages\django\db\models\sql\compiler.py", line 1416, in execute_sql
    cursor.execute(sql, params)
  File "D:\django projects\exel_data\venv\lib\site-packages\django\db\backends\utils.py", line 98, in execute
    return super().execute(sql, params)
  File "D:\django projects\exel_data\venv\lib\site-packages\django\db\backends\utils.py", line 66, in execute
    return self._execute_with_wrappers(sql, params, many=False, executor=self._execute)
  File "D:\django projects\exel_data\venv\lib\site-packages\django\db\backends\utils.py", line 75, in _execute_with_wrappers
    return executor(sql, params, many, context)
  File "D:\django projects\exel_data\venv\lib\site-packages\django\db\backends\utils.py", line 84, in _execute
    return self.cursor.execute(sql, params)
  File "D:\django projects\exel_data\venv\lib\site-packages\django\db\utils.py", line 90, in __exit__
    raise dj_exc_value.with_traceback(traceback) from exc_value
  File "D:\django projects\exel_data\venv\lib\site-packages\django\db\backends\utils.py", line 84, in _execute
    return self.cursor.execute(sql, params)
  File "D:\django projects\exel_data\venv\lib\site-packages\django\db\backends\mysql\base.py", line 73, in execute
    return self.cursor.execute(query, args)
  File "D:\django projects\exel_data\venv\lib\site-packages\MySQLdb\cursors.py", line 206, in execute
    res = self._query(query)
  File "D:\django projects\exel_data\venv\lib\site-packages\MySQLdb\cursors.py", line 319, in _query
    db.query(q)
  File "D:\django projects\exel_data\venv\lib\site-packages\MySQLdb\connections.py", line 254, in query
    _mysql.connection.query(self, query)
django.db.utils.IntegrityError: (1062, "Duplicate entry 'ali@gmail.com' for key 'project_person.project_person_email_82bd4bf0_uniq'")
INFO:django.utils.autoreload:D:\django projects\exel_data\project\models.py changed, reloading.
INFO:django.utils.autoreload:D:\django projects\exel_data\project\models.py changed, reloading.
INFO:django.utils.autoreload:D:\django projects\exel_data\project\models.py changed, reloading.
ERROR:django.request:Internal Server Error: /upload_excel
Traceback (most recent call last):
  File "D:\django projects\exel_data\venv\lib\site-packages\django\core\handlers\exception.py", line 47, in inner
    response = get_response(request)
  File "D:\django projects\exel_data\venv\lib\site-packages\django\core\handlers\base.py", line 181, in _get_response
    response = wrapped_callback(request, *callback_args, **callback_kwargs)
  File "D:\django projects\exel_data\project\views.py", line 29, in Import_excel_file
    save_obj(row)
  File "D:\django projects\exel_data\project\store_data.py", line 7, in save_obj
    Person.objects.create(first_name=row.first_name, last_name=row.last_name, email=row.email, created_at=now, job_title=row.job_title
  File "D:\django projects\exel_data\venv\lib\site-packages\django\db\models\manager.py", line 85, in manager_method
    return getattr(self.get_queryset(), name)(*args, **kwargs)
  File "D:\django projects\exel_data\venv\lib\site-packages\django\db\models\query.py", line 453, in create
    obj.save(force_insert=True, using=self.db)
  File "D:\django projects\exel_data\venv\lib\site-packages\django\db\models\base.py", line 726, in save
    self.save_base(using=using, force_insert=force_insert,
  File "D:\django projects\exel_data\venv\lib\site-packages\django\db\models\base.py", line 763, in save_base
    updated = self._save_table(
  File "D:\django projects\exel_data\venv\lib\site-packages\django\db\models\base.py", line 868, in _save_table
    results = self._do_insert(cls._base_manager, using, fields, returning_fields, raw)
  File "D:\django projects\exel_data\venv\lib\site-packages\django\db\models\base.py", line 906, in _do_insert
    return manager._insert(
  File "D:\django projects\exel_data\venv\lib\site-packages\django\db\models\manager.py", line 85, in manager_method
    return getattr(self.get_queryset(), name)(*args, **kwargs)
  File "D:\django projects\exel_data\venv\lib\site-packages\django\db\models\query.py", line 1270, in _insert
    return query.get_compiler(using=using).execute_sql(returning_fields)
  File "D:\django projects\exel_data\venv\lib\site-packages\django\db\models\sql\compiler.py", line 1415, in execute_sql
    for sql, params in self.as_sql():
  File "D:\django projects\exel_data\venv\lib\site-packages\django\db\models\sql\compiler.py", line 1358, in as_sql
    value_rows = [
  File "D:\django projects\exel_data\venv\lib\site-packages\django\db\models\sql\compiler.py", line 1359, in <listcomp>
    [self.prepare_value(field, self.pre_save_val(field, obj)) for field in fields]
  File "D:\django projects\exel_data\venv\lib\site-packages\django\db\models\sql\compiler.py", line 1359, in <listcomp>
    [self.prepare_value(field, self.pre_save_val(field, obj)) for field in fields]
  File "D:\django projects\exel_data\venv\lib\site-packages\django\db\models\sql\compiler.py", line 1300, in prepare_value
    value = field.get_db_prep_save(value, connection=self.connection)
  File "D:\django projects\exel_data\venv\lib\site-packages\django\db\models\fields\__init__.py", line 842, in get_db_prep_save
    return self.get_db_prep_value(value, connection=connection, prepared=False)
  File "D:\django projects\exel_data\venv\lib\site-packages\django\db\models\fields\__init__.py", line 1427, in get_db_prep_value
    value = self.get_prep_value(value)
  File "D:\django projects\exel_data\venv\lib\site-packages\django\db\models\fields\__init__.py", line 1406, in get_prep_value
    value = super().get_prep_value(value)
  File "D:\django projects\exel_data\venv\lib\site-packages\django\db\models\fields\__init__.py", line 1266, in get_prep_value
    return self.to_python(value)
  File "D:\django projects\exel_data\venv\lib\site-packages\django\db\models\fields\__init__.py", line 1367, in to_python
    parsed = parse_datetime(value)
  File "D:\django projects\exel_data\venv\lib\site-packages\django\utils\dateparse.py", line 107, in parse_datetime
    match = datetime_re.match(value)
TypeError: expected string or bytes-like object
INFO:django.utils.autoreload:D:\django projects\exel_data\project\models.py changed, reloading.
ERROR:django.request:Internal Server Error: /upload_excel
Traceback (most recent call last):
  File "D:\django projects\exel_data\venv\lib\site-packages\django\core\handlers\exception.py", line 47, in inner
    response = get_response(request)
  File "D:\django projects\exel_data\venv\lib\site-packages\django\core\handlers\base.py", line 181, in _get_response
    response = wrapped_callback(request, *callback_args, **callback_kwargs)
  File "D:\django projects\exel_data\project\views.py", line 29, in Import_excel_file
    save_obj(row)
  File "D:\django projects\exel_data\project\store_data.py", line 7, in save_obj
    Person.objects.create(first_name=row.first_name, last_name=row.last_name, email=row.email, created_at=now, job_title=row.job_title
  File "D:\django projects\exel_data\venv\lib\site-packages\django\db\models\manager.py", line 85, in manager_method
    return getattr(self.get_queryset(), name)(*args, **kwargs)
  File "D:\django projects\exel_data\venv\lib\site-packages\django\db\models\query.py", line 453, in create
    obj.save(force_insert=True, using=self.db)
  File "D:\django projects\exel_data\venv\lib\site-packages\django\db\models\base.py", line 726, in save
    self.save_base(using=using, force_insert=force_insert,
  File "D:\django projects\exel_data\venv\lib\site-packages\django\db\models\base.py", line 763, in save_base
    updated = self._save_table(
  File "D:\django projects\exel_data\venv\lib\site-packages\django\db\models\base.py", line 868, in _save_table
    results = self._do_insert(cls._base_manager, using, fields, returning_fields, raw)
  File "D:\django projects\exel_data\venv\lib\site-packages\django\db\models\base.py", line 906, in _do_insert
    return manager._insert(
  File "D:\django projects\exel_data\venv\lib\site-packages\django\db\models\manager.py", line 85, in manager_method
    return getattr(self.get_queryset(), name)(*args, **kwargs)
  File "D:\django projects\exel_data\venv\lib\site-packages\django\db\models\query.py", line 1270, in _insert
    return query.get_compiler(using=using).execute_sql(returning_fields)
  File "D:\django projects\exel_data\venv\lib\site-packages\django\db\models\sql\compiler.py", line 1415, in execute_sql
    for sql, params in self.as_sql():
  File "D:\django projects\exel_data\venv\lib\site-packages\django\db\models\sql\compiler.py", line 1358, in as_sql
    value_rows = [
  File "D:\django projects\exel_data\venv\lib\site-packages\django\db\models\sql\compiler.py", line 1359, in <listcomp>
    [self.prepare_value(field, self.pre_save_val(field, obj)) for field in fields]
  File "D:\django projects\exel_data\venv\lib\site-packages\django\db\models\sql\compiler.py", line 1359, in <listcomp>
    [self.prepare_value(field, self.pre_save_val(field, obj)) for field in fields]
  File "D:\django projects\exel_data\venv\lib\site-packages\django\db\models\sql\compiler.py", line 1300, in prepare_value
    value = field.get_db_prep_save(value, connection=self.connection)
  File "D:\django projects\exel_data\venv\lib\site-packages\django\db\models\fields\__init__.py", line 842, in get_db_prep_save
    return self.get_db_prep_value(value, connection=connection, prepared=False)
  File "D:\django projects\exel_data\venv\lib\site-packages\django\db\models\fields\__init__.py", line 1427, in get_db_prep_value
    value = self.get_prep_value(value)
  File "D:\django projects\exel_data\venv\lib\site-packages\django\db\models\fields\__init__.py", line 1406, in get_prep_value
    value = super().get_prep_value(value)
  File "D:\django projects\exel_data\venv\lib\site-packages\django\db\models\fields\__init__.py", line 1266, in get_prep_value
    return self.to_python(value)
  File "D:\django projects\exel_data\venv\lib\site-packages\django\db\models\fields\__init__.py", line 1367, in to_python
    parsed = parse_datetime(value)
  File "D:\django projects\exel_data\venv\lib\site-packages\django\utils\dateparse.py", line 107, in parse_datetime
    match = datetime_re.match(value)
TypeError: expected string or bytes-like object
INFO:django.utils.autoreload:D:\django projects\exel_data\project\models.py changed, reloading.
ERROR:django.request:Internal Server Error: /upload_excel
Traceback (most recent call last):
  File "D:\django projects\exel_data\venv\lib\site-packages\django\db\backends\utils.py", line 84, in _execute
    return self.cursor.execute(sql, params)
  File "D:\django projects\exel_data\venv\lib\site-packages\django\db\backends\mysql\base.py", line 73, in execute
    return self.cursor.execute(query, args)
  File "D:\django projects\exel_data\venv\lib\site-packages\MySQLdb\cursors.py", line 206, in execute
    res = self._query(query)
  File "D:\django projects\exel_data\venv\lib\site-packages\MySQLdb\cursors.py", line 319, in _query
    db.query(q)
  File "D:\django projects\exel_data\venv\lib\site-packages\MySQLdb\connections.py", line 254, in query
    _mysql.connection.query(self, query)
MySQLdb._exceptions.IntegrityError: (1062, "Duplicate entry 'ALI@gmail.com' for key 'project_person.project_person_email_82bd4bf0_uniq'")

The above exception was the direct cause of the following exception:

Traceback (most recent call last):
  File "D:\django projects\exel_data\venv\lib\site-packages\django\core\handlers\exception.py", line 47, in inner
    response = get_response(request)
  File "D:\django projects\exel_data\venv\lib\site-packages\django\core\handlers\base.py", line 181, in _get_response
    response = wrapped_callback(request, *callback_args, **callback_kwargs)
  File "D:\django projects\exel_data\project\views.py", line 29, in Import_excel_file
    save_obj(row)
  File "D:\django projects\exel_data\project\store_data.py", line 7, in save_obj
    Person.objects.create(first_name=row.first_name, last_name=row.last_name, email=row.email, created_at=now, job_title=row.job_title
  File "D:\django projects\exel_data\venv\lib\site-packages\django\db\models\manager.py", line 85, in manager_method
    return getattr(self.get_queryset(), name)(*args, **kwargs)
  File "D:\django projects\exel_data\venv\lib\site-packages\django\db\models\query.py", line 453, in create
    obj.save(force_insert=True, using=self.db)
  File "D:\django projects\exel_data\venv\lib\site-packages\django\db\models\base.py", line 726, in save
    self.save_base(using=using, force_insert=force_insert,
  File "D:\django projects\exel_data\venv\lib\site-packages\django\db\models\base.py", line 763, in save_base
    updated = self._save_table(
  File "D:\django projects\exel_data\venv\lib\site-packages\django\db\models\base.py", line 868, in _save_table
    results = self._do_insert(cls._base_manager, using, fields, returning_fields, raw)
  File "D:\django projects\exel_data\venv\lib\site-packages\django\db\models\base.py", line 906, in _do_insert
    return manager._insert(
  File "D:\django projects\exel_data\venv\lib\site-packages\django\db\models\manager.py", line 85, in manager_method
    return getattr(self.get_queryset(), name)(*args, **kwargs)
  File "D:\django projects\exel_data\venv\lib\site-packages\django\db\models\query.py", line 1270, in _insert
    return query.get_compiler(using=using).execute_sql(returning_fields)
  File "D:\django projects\exel_data\venv\lib\site-packages\django\db\models\sql\compiler.py", line 1416, in execute_sql
    cursor.execute(sql, params)
  File "D:\django projects\exel_data\venv\lib\site-packages\django\db\backends\utils.py", line 98, in execute
    return super().execute(sql, params)
  File "D:\django projects\exel_data\venv\lib\site-packages\django\db\backends\utils.py", line 66, in execute
    return self._execute_with_wrappers(sql, params, many=False, executor=self._execute)
  File "D:\django projects\exel_data\venv\lib\site-packages\django\db\backends\utils.py", line 75, in _execute_with_wrappers
    return executor(sql, params, many, context)
  File "D:\django projects\exel_data\venv\lib\site-packages\django\db\backends\utils.py", line 84, in _execute
    return self.cursor.execute(sql, params)
  File "D:\django projects\exel_data\venv\lib\site-packages\django\db\utils.py", line 90, in __exit__
    raise dj_exc_value.with_traceback(traceback) from exc_value
  File "D:\django projects\exel_data\venv\lib\site-packages\django\db\backends\utils.py", line 84, in _execute
    return self.cursor.execute(sql, params)
  File "D:\django projects\exel_data\venv\lib\site-packages\django\db\backends\mysql\base.py", line 73, in execute
    return self.cursor.execute(query, args)
  File "D:\django projects\exel_data\venv\lib\site-packages\MySQLdb\cursors.py", line 206, in execute
    res = self._query(query)
  File "D:\django projects\exel_data\venv\lib\site-packages\MySQLdb\cursors.py", line 319, in _query
    db.query(q)
  File "D:\django projects\exel_data\venv\lib\site-packages\MySQLdb\connections.py", line 254, in query
    _mysql.connection.query(self, query)
django.db.utils.IntegrityError: (1062, "Duplicate entry 'ALI@gmail.com' for key 'project_person.project_person_email_82bd4bf0_uniq'")
DEBUG:root:('Valid Row : 3', 'Invalid Row: 0')
INFO:django.utils.autoreload:D:\django projects\exel_data\CSV_data\update_emails_from_CSV_file.py changed, reloading.
INFO:django.utils.autoreload:D:\django projects\exel_data\CSV_data\update_emails_from_CSV_file.py changed, reloading.
DEBUG:root:('Valid Row : 3', 'Invalid Row: 0')
INFO:django.utils.autoreload:D:\django projects\exel_data\project\store_data.py changed, reloading.
INFO:django.utils.autoreload:D:\django projects\exel_data\project\store_data.py changed, reloading.
INFO:django.utils.autoreload:D:\django projects\exel_data\project\views.py changed, reloading.
ERROR:django.request:Internal Server Error: /upload_csv
Traceback (most recent call last):
  File "D:\django projects\exel_data\venv\lib\site-packages\django\core\handlers\exception.py", line 47, in inner
    response = get_response(request)
  File "D:\django projects\exel_data\venv\lib\site-packages\django\core\handlers\base.py", line 181, in _get_response
    response = wrapped_callback(request, *callback_args, **callback_kwargs)
  File "D:\django projects\exel_data\CSV_data\csv_file.py", line 26, in Import_csv_file
    save_obj(row)
TypeError: save_obj() missing 1 required positional argument: 'request'
ERROR:django.request:Internal Server Error: /upload_excel
Traceback (most recent call last):
  File "D:\django projects\exel_data\venv\lib\site-packages\django\utils\datastructures.py", line 76, in __getitem__
    list_ = super().__getitem__(key)
KeyError: ('file', None)

During handling of the above exception, another exception occurred:

Traceback (most recent call last):
  File "D:\django projects\exel_data\venv\lib\site-packages\django\core\handlers\exception.py", line 47, in inner
    response = get_response(request)
  File "D:\django projects\exel_data\venv\lib\site-packages\django\core\handlers\base.py", line 181, in _get_response
    response = wrapped_callback(request, *callback_args, **callback_kwargs)
  File "D:\django projects\exel_data\project\views.py", line 13, in Import_excel_file
    myfile = request.FILES['file', None]
  File "D:\django projects\exel_data\venv\lib\site-packages\django\utils\datastructures.py", line 78, in __getitem__
    raise MultiValueDictKeyError(key)
django.utils.datastructures.MultiValueDictKeyError: ('file', None)
INFO:django.utils.autoreload:D:\django projects\exel_data\project\views.py changed, reloading.
